Workbook

Sheet 표지
B7: 요구사항명세서
B9: 감사정보시스템 클라우드 전환 재구축
D17: 작성자 | F17: 김병원
D18: 작성 상태 | F18: 최종
D19: 최종 개정일 | F19: 45621
A22: 본 문서는 어떠한 경우에도 공식적인 허가 없이 복사하거나 외부로 유출하는 일체의 행위를 금함

Sheet 개정이력
E2: 개정 이력
A4: 일자 | B4: 버전 | C4: 주요 내용 | I4: 작성자 | J4: 승인자
A5: 45607 | B5: 0.1 | C5: 초안 | I5: 남상현 | J5: -
A6: 45621 | B6: 0.9 | C6: 현업리뷰후 정리본 | I6: 김병원 | J6: 유경근
A7: 45621 | B7: 0.91 | C7: 품질담당자 리뷰 | I7: 남상현 | J7: 유경근
A8: 45622 | B8: 1.00 | C8: 최종 완료 | I8: 남상현 | J8: 유경근

Sheet (요건분리 전)요구사항명세서
A1: Biz요건ID | B1: Biz요건명 | C1: 요구사항구분 | D1: 생성단계 | E1: 상태구분 | F1: 출처 | G1: 요구사항ID | H1: 요구사항명 | I1: 기능/비기능요구사항(취합정리 5/25) | J1: 사용자권한요구사항 | K1: 의뢰부서 | L1: 요구사항처리담당팀 | M1: 검토 상태 | N1: 검토의견 | O1: 변경요구사항ID | P1: 변경일 | Q1: 근기문서 | R1: ACE | S1: 반영점검사항 | T1: 반영여부(5.26) | U1: 수행사 담당자 | V1: 업무상세 | W1: 요구사항추적표담당자 | X1: 특이사항 | Y1: 조건부승인 확정예정일자(YYYY-MM-DD)
A2: Biz-001 | B2: 공통 | C2: 비기능 | E2: 신규 | F2: 구축요건정의서 | G2: BFE-10001 | H2: UX/UI | I2: - 스타뱅킹 지원 OS 및 기종별 최적화된 UX/UI 적용 ㅇ 기기 해상도에 따른 텍스트/이미지 표시오류 최소화 ㅇ 폴더블폰, 태블릿PC용 특화 UX/UI 구현하지 않음 ㅇ KB국민은행 모바일웹 개발하지 않음 ㅇ 2021년 기준의 아이폰, 안드로이드폰 OS 버전별 16대 기기(폰 14대, 태블릿PC) 테스트 진행 참고 - 스타뱅킹 UX/UI 가이드 준수 - 트렌디한 디자인 | K2: 스타뱅킹2부_biz | Q2: KB스타뱅킹 금융상품몰 개편_회의록_요구사항분석_공통,수신,여신_20220511.docx
A3: Biz-001 | B3: 공통 | C3: 비기능 | E3: 신규 | F3: 구축요건정의서 | G3: BFE-10002 | H3: 고객 친화적 용어 사용 | I3: - 마케팅 소구 포인트 반영된 간결한 문구, 고객친화적/직관적 설명 - ‘고객언어관리’ 시스템을 이용한 용어 교정 | K3: 스타뱅킹2부_biz
A4: Biz-001 | B4: 공통 | C4: 비기능 | E4: 신규 | F4: 구축요건정의서 | G4: BFE-10003 | H4: 앱접근성 | I4: -앱접근성 가이드 준수(솔루션 점검 포함) | K4: 스타뱅킹2부_biz
A5: Biz-002 | B5: 상품탐색 | C5: 기능 | D5: 요구사항정의 | E5: 신규 | F5: 구축요건정의서 | G5: BFE-20001 | H5: 검색기능 고도화 | I5: - 금융상품몰 內 검색 범위 확장 ㅇ [As-Is] 개별상품 카테고리, ‘상품명’ 기준 검색만 가능 ㅇ [To-Be] 전체상품 통합검색, 키워드(태그)검색 제공 ㅇ 통합검색(솔루션)이 아닌 DB검색으로 제공하고 검색결과는 별도 화면으로 제공 - 검색기능 정밀화 ㅇ 대소문자 호환 ㅇ 최근검색어 제공 ㅇ 검색창 하단에 추천 키워드(테마) 제시 ㅇ 상품검색 결과시 상품군별 최대 3개 상품까지만 표출, 추가 리스트는 '더보기' 버튼으로 처리 ㅇ 인기검색어/유의어 기능 추가 및 해당 기능은 어드민에서 관리하도록 구현 ㅇ 자동완성 : DB 기반 개발 검토 - 검색기능 제공 화면 확대 ㅇ 금융상품 Main : 전체 상품 카테고리 상품검색 > 상품군별 구분 표시(예적금/대출/펀드 등) ㅇ 금융상품 서브메인 : 해당 카테고리만 한정하여 상품검색 > 적용 상품 카테고리 : 수신, 여신, 펀드, 신탁, ISA, 청약, 외화예금, 퇴직연금, 보험, 골드투자통장 > 비예금 상품(투자성 상품)의 경우 당일 투자성향 분석 미완료 고객은 검색결과 리스트를 표시하지 않으며, 투자성향분석이후 확인 가능하다는 노티 제공(투자성향분석 화면으로 이동하도록 처리) > 상세(필터)검색 신규제공 : 예/적금, 신탁형 ISA > 상세(필터)검색 개선 : 펀드, 신탁, ISA ㅇ 예/적금 : 필터 방식 예적금 찾기 기능 신설 > 상품유형(적금/예금), 이자지급방식, 가입기간, 신규금액, 우대금리항목 추가 등 필터 선택방식 적용 - 예적금 공동 검색으로 할지, 예금/적금 분리할지 의사결정 필요 ㅇ 펀드: 펀드 카테고리 내 상품명/키워드(태그) 검색 > 펀드는 종목명 (우선순위 : 펀드명>키워드>종목 편입비중) 검색 가능하도록 구성 > 펀드유형(국내주식형, 해외주식형 등), 테마/지역, 위험등급 등 필터 선택 가능하게 구성 ㅇ 신탁: 신탁 카테고리 내 상품명/키워드(태그) 검색 > 특정금전신탁(ETF/ELS) : 금융상품몰 검색 결과에 특정금전신탁 상품 노출 ㄴ 법률검토 결과: 메인화면에는 노출(X)하지 않으며, 신탁 서브메인에만 노출하도록 구성 ㅇ 유언대용신탁 : 비대면 판매상품 제외 ㅇ ISA : 금융상품몰의 ISA 검색은 신탁형ISA, 일임형ISA 레벨에서 결과를 표시하도록 구성(신탁형ISA, 일임형ISA 상품 1개씩 구성 형태) > 신탁형ISA 내 상품 검색 기능 개발 (계정계 상품 연동 고려해야 하며 가능 여부 개발검토 후 별도 협의 예정) : ~5/27(임미정과장) ㄴ 상품가입/운용지시 시 세부검색 기능 제공 > 일임형ISA 내 상품 검색은 이미 개발되어 있으며 그대로 적용 ㅇ 퇴직연금: 퇴직연금 카테고리 내 상품명/키워드(태그) 검색 (상품운용지시 또는 상품변경 화면) > 금융상품몰 메인 검색에서는 IRP 껍데기(?) 검색 > 상품검색시 IRP '껍데기' 표시를 위한 어드민 기능 개발(상품검색용) | K5: 스타뱅킹2부_biz | Q5: KB스타뱅킹 금융상품몰 개편_회의록_요구사항분석_신탁, ISA_20220512.docx KB스타뱅킹 금융상품몰 개편_회의록_요구사항분석_스타뱅킹3부리뷰_20220525.docx
A6: Biz-002 | B6: 상품탐색 | C6: 기능 | E6: 신규 | F6: 구축요건정의서 | G6: BFE-20002 | H6: 상품 카테고리 정비 | I6: - 금융상품몰 內 상품 카테고리명 및 순서 사용자 중심 개선 ㅇ 카테고리 변경에 따라 통합어드민>마케팅>상품게시관리>금융상품 서브메인(스타뱅킹)의 카테고리도 변경 대응 필요 ㅇ 화면 크기로 인하여 스뱅은 스뱅에서만 판매하는 상품만 노출(스뱅, 인뱅 상이) ㅇ 개인화(사용자) 기준 순서 변경 기능 제공 - 사용률, 페이지뷰 낮은 카테고리/배너 통합 또는 삭제 - 향후 계열사 및 외부 상품 확장 가능성을 고려하여 상품 카테고리 관리 기능(상품관리 아님) 설계 | K6: 스타뱅킹2부_biz | Q6: KB스타뱅킹 금융상품몰 개편_회의록_요구사항분석_신탁, ISA_20220512.docx KB스타뱅킹 금융상품몰 개편_회의록_요구사항분석_청약_20220516.docx
A7: Biz-002 | B7: 상품탐색 | C7: 기능 | E7: 신규 | F7: 구축요건정의서 | G7: BFE-20003 | H7: 데이터 활용 다양화 | I7: - D/W에 적재된 데이터 기반 통계량을 반영한 검색 제공 - 고객의 흥미를 유발할 수 있는 다양한 테마 및 비교군 기획 (테마군에 대해서는 현업 정의 후 전달) : 조건부수용 - 데이터 분석 및 모델링하여 테마별 신규 데이터 D/W 적재 | K7: 스타뱅킹2부_biz | Q7: KB스타뱅킹 금융상품몰 개편_회의록_요구사항분석_신탁, ISA_20220512.docx | T7: 조건부수용
A8: Biz-002 | B8: 상품탐색 | C8: 기능 | E8: 신규 | F8: 구축요건정의서 | G8: BFE-20004 | H8: 명확한 추천사유 제시 | I8: - 상품 추천의 이유를 명확히 설명 ㅇ 가입비율, 혜택, 트렌드 등 관련 데이터 근거 제시 ㅇ 고객 친화적인 용어 및 화법 사용 > 추천사유를 풀어서 친화적 용어 및 화법 사용, 데이터 활용 추천 근기 제시 ㄴ 가입비율, 혜택, 트렌드 등 관련 데이터 근거를 제시하는 내용 표현 (추천사유 예시 : Z세대에게 필수, 똑똑한 직장인이라면 세금혜택도 챙겨야죠, 요즘 트렌드는 전기차) (관련근거 예시 : Z세대 가입 비율, 절세 1년에 최대 얼마, 전기차 검색 그래프 등) > Peer Group 비고, 직업/연령대별 추천/트렌드 반영 등의 추천 이유 설명 ㅇ 추천테마, 추천사유의 데이터 근기 및 상세내용은 데이터분석부 협업 필요(현업) : 조건부수용 > 데이터 제공 방식, 화면 구현 방안 등 유관부서 세부 협의 필요 > 데이터분석부에서 추천사유코드 전달하고, 어드민에서 추천사유명 설정 ㄴ 통합어드민 > 뉴스타뱅킹에 관련 기능이 존재함(참고) | K8: 스타뱅킹2부_biz | Q8: KB스타뱅킹 금융상품몰 개편_회의록_요구사항분석_신탁, ISA_20220512.docx KB스타뱅킹 금융상품몰 개편_회의록_요구사항분석_보험_20220513.docx | T8: 조건부수용
A9: Biz-002 | B9: 상품탐색 | C9: 기능 | E9: 신규 | F9: 구축요건정의서 | G9: BFE-20005 | H9: 연관상품 추천 | I9: -개별 상품정보 화면 內 연관상품 추천 제공 ㅇ 해당상품 가입자들이 많이 가입한 또 다른 상품 ㅇ 동일테마에 해당하는 유사상품 ㅇ 연관상품 제공 카테고리: 수신, 여신, 펀드, 신탁, ISA, 청약, 외화예금, 퇴직연금, 보험, 골드투자통장 ㅇ 비예금 상품(투자성 상품)의 경우 투자성향분석 유무에 따라 노출 필요 > 투자성향분석 유무에 대한 케이스 정리 후 반영 ㅇ 추천상품 수 : 2~3개 정도 노출 (화면 구성 후 적정 숫자 결정) ㅇ 연관상품 추천은 당행 상품만 진행 | K9: 스타뱅킹2부_biz | Q9: KB스타뱅킹 금융상품몰 개편_회의록_요구사항분석_공통,수신,여신_20220511.docx KB스타뱅킹 금융상품몰 개편_회의록_요구사항분석_펀드_20220512.docx KB스타뱅킹 금융상품몰 개편_회의록_요구사항분석_신탁, ISA_20220512.docx
A10: Biz-002 | B10: 상품탐색 | C10: 기능 | E10: 신규 | F10: 구축요건정의서 | G10: BFE-20006 | H10: 상품가입 이어가기주) 개선 | I10: - 전체 상품 카테고리로 범위 확대 - 개인화 및 시인성 개선 ㅇ ‘간편신규’, ‘가입진행중’, ‘장바구니’에 해당하는 고객이 진입한경우 명확하게노출(이어가기 대상상품 없을 경우에는 미노출) ㅇ 메뉴(서비스)명 직관적으로 변경 - 상품정보 공유하기 알림 포맷 개선 ㅇ 공유상품의 특징 및 마케팅 포인트 공유정보에 포함 ㅇ SNS 알림에 적합한 이미지 및 문구 사용 ※ 주) 상품가입 / 이어가기 등 공통성 메뉴 1. 장바구니, 2. 영업점 전송, 3. 가입진행중, 4. 간편신규, 5. 공유하기 - 가입 프로세스 중 이어가기 임시저장 (기술검토 후 반영여부 결정 예정) ㅇ [As-is] 임시저장 버튼 클릭 시 저장 - 장바구니의 상품에 대해 일정기간 저장 후 삭제 기능 개발 | K10: 스타뱅킹2부_biz | Q10: KB스타뱅킹 금융상품몰 개편_회의록_요구사항분석_공통,수신,여신_20220511.docx KB스타뱅킹 금융상품몰 개편_회의록_요구사항분석_신탁, ISA_20220512.docx KB스타뱅킹 금융상품몰 개편_회의록_요구사항분석_펀드_20220512.docx KB스타뱅킹 금융상품몰 개편_회의록_요구사항분석_퇴직연금_20220513.docx KB스타뱅킹 금융상품몰 개편_회의록_요구사항분석_보험_20220513.docx KB스타뱅킹 금융상품몰 개편_회의록_요구사항분석_청약_20220516.docx
A11: Biz-002 | B11: 상품탐색 | C11: 기능 | E11: 신규 | F11: 구축요건정의서 | G11: BFE-20007 | H11: 상품탐색 히스토리 관리 | I11: -최근 조회(상품상세정보)한 상품 리스트 자동 저장 ㅇ 타임라인 형태로 리스트 표출(상품명, 검색일시 표시) ㅇ 타임라인 표시 조회 기준 : 상품상세정보 페이지 조회 기준 ㅇ 리스트 선택 시 해당상품 상세페이지로 이동 ※ 투자상품은 당일 투자성향분석 선행 후 가입가능 상품만 상세페이지로 이동 ㅇ 가입 종료 상품 표시(비활성화 처리 등) ㅇ 노출 상품개수는 최근 20개(성능 감안하여 조정 가능) ㅇ 타임라인 데이터는 앱내 저장 | K11: 스타뱅킹2부_biz
A12: Biz-002 | B12: 상품탐색 | C12: 기능 | E12: 신규 | F12: 구축요건정의서 | G12: BFE-20008 | H12: 상품비교 | I12: -2개 상품의 주요특징 비교 기능 제공 ㅇ 상품 카테고리별 비교 항목 설정 | K12: 스타뱅킹2부_biz | Q12: KB스타뱅킹 금융상품몰 개편_회의록_요구사항분석_신탁, ISA_20220512.docx KB스타뱅킹 금융상품몰 개편_회의록_요구사항분석_펀드_20220512.docx KB스타뱅킹 금융상품몰 개편_회의록_요구사항분석_퇴직연금_20220513.docx KB스타뱅킹 금융상품몰 개편_회의록_요구사항분석_보험_20220513.docx
A13: Biz-003 | B13: 상품조회 | C13: 기능 | E13: 신규 | F13: 구축요건정의서 | G13: BFE-30001 | H13: 혜택 시뮬레이션 | I13: - 우대금리 혜택 시뮬레이션 제공 ㅇ 개인화 우대금리 요소 반영한 금리 안내 ㅇ 우대금리 혜택 시뮬레이션 적용 카테고리 : 수신상품만 적용 (여신은 제외) ㅇ 모든 우대금리 조회 : 우대금리는 일반적으로 만기 시점에 달성되어 대부분 달성 안 된 경우가 많으니 해당 내용 고려하여 적용 ㅇ 우대금리, 일부 상품군에서는 상품 안내(목록, 상세 등) 화면에서도 노출 - 상품계산기를 개별상품 콘텐츠 내 배치 ㅇ 해당상품에 대한 기본정보 디폴트 세팅 후 계산 가능 - 계산기 추가 개발 및 적용 ㅇ 투자상품 계산기(과거수익률 기반 모의투자값 계산) > 대상상품 : 펀드 (연금저축펀드, MMF 제외) > 인터넷뱅킹에 구현되어있는 펀드 예상 수익률 계산기 개선 적용 (개인뱅킹>금융상품>펀드>펀드 입금/환매/조회>펀드수익률 시뮬레이션) > 상품 상세 화면에 제공 > 계산 기준펀드를 해당 상품으로 자동 세팅 > 상품 내 계산기 표출여부는 어드민에서 관리 - 만기 예상금액 계산기를 상품 상세화면에 제공 (예금, 적금 ㅇ 해당상품에 대한 기본정보 디폴트 세팅 후 계산 > 디폴트 데이터 : 월납입금액, 납입기간, 우대금리(현재 충족된 항목은 체크) > 우대금리는 기간마다 기본이율이 다르므로, 선택된 기간에 맞춰 기본이율이 옵션으로 설정되었으면 함 ㅇ 현재 미충족된 우대금리 항목은 수동으로 체크 가능하도록 구현 (예금, 적금, 대출) ㅇ 결과값 : 적용 금리, 만기예상액, 총납입액, 기본금리/우대금리 반영 이자금액 구분 표시 (예금, 적금) - 상품계산기 ㅇ 예금 > 해당상품에 대한 기본정보 디폴트 세팅 후 계산 ㄴ 디폴트 데이터 : 가입금액, 가입기간, 우대금리(현재 충족된 항목은 체크) ㅇ 적금 > 해당상품에 대한 기본정보 디폴트 세팅 후 계산 ㄴ 디폴트 데이터 : 월납입금액, 납입기간, 우대금리(현재 충족된 항목은 체크) - 혜택 시뮬레이션 ㅇ 펀드 > 펀드 모의투자 시뮬레이션 제공 > 과거수익률 기반(ex. 지난 3년동안 10만원씩 투자했다면 현재 수익률은?) > 인터넷뱅킹의 펀드 수익률시뮬레이셔 기능 참조하여 개발 적용 ㅇ 적금 > 우대금리 혜택 시뮬레이션 제공 > 현재 기준 개인화 우대금리 항목 충족여부 반영한 개인화 금리 시각화 안내 > 현재 미충족 항목의 경우 해당 서비스 신청 페이지 연계 > 구현가능 범위 및 데이터 제공방식 등은 데이터분석부와 협의 필요 : 6/3일까지 확인 후 개발범위 확정 : 조건부수용 | K13: 스타뱅킹2부_biz | Q13: KB스타뱅킹 금융상품몰 개편_회의록_요구사항분석_공통,수신,여신_20220511.docx KB스타뱅킹 금융상품몰 개편_회의록_요구사항분석_펀드_20220512.docx KB스타뱅킹 금융상품몰 개편_회의록_요구사항분석_퇴직연금_20220513.docx | T13: 조건부수용
A14: Biz-003 | B14: 상품조회 | C14: 기능 | E14: 신규 | F14: 구축요건정의서 | G14: BFE-30002 | H14: 금융상품몰 화면 간소화 | I14: - 전체적인 Tone&Manner통일하여 화면 설계 ㅇ 메인/서브메인 화면 및 상품 상세화면 재구성 > 메인화면에 통합검색창 제공 > 메인화면에 이어가기(간편신규/가입진행중/장바구니) 기능 제공 ㄴ 이어가기는 해당사항이 있는 고객에게만 노출 > 핵심/추천상품은 3개 이하 노출 ㅇ 주요정보/부수정보 구분하여 주요정보 중심의 화면 구성 ㅇ 이미지/그래프/애니메이션 적극 활용(텍스트 최소화) - 상품 게시 간소화 ㅇ 핵심상품(3개 이하) 전면 배치 ㅇ 펀드상품 노출방식 개선(동일상품 클래스별 모두 노출하지 않고 대표클래스 상품노출) ㅇ 업무범위 : 수신, 외화예금, 대출, 펀드, 신탁, ISA, 청약, 퇴직연금, 보험, 은행-증권, 카드, 골드투자통장, 골드바/실버바 - 상품 목록에서 '가입하기' 버튼 삭제, 랜딩페이지 일원화 ㅇ [As-Is] (수신, 대출 등) 상품 목록 영역과 '가입하기' 버튼 랜딩페이지 상이 ㅇ [To-Be] '가입하기' 버튼 삭제, 상품 목록 클릭 시 상품 상세 화면으로 랜딩 - 서브메인 구성 : 입출금 / 적금 / 예금 ㅇ 개인화된 추천상품 노출 : 명확한 추천 사유 상단 표시 ㅇ '금융쿠폰', ' 금리우대쿠폰', 관련 이벤트 존재 시 표시 > 금융쿠폰/금리우대쿠폰은 발급 대상자 or 쿠폰 보유자 체크해서 표시 ㅇ 해시태그 노출 > as-is 의 해시태그 항목보다 다양한 최신 트랜드 및 검색어 반영 ㅇ 대표 상품 2~3개 게시 > 한번에 3개 이하로 표출, '더보기' 버튼으로 추가 리스트 표출 > 상품 선택 시 상품 상세 페이지로 연결 - 서브메인 구성 : 대출 ㅇ 금리인하권 관련 내용은 대상자에게만 표출 > [As-is] 금리 인하권 상품이 있을 경우 해당계좌노출, 금리 인하 상품이 없을 경우 ‘금리인하 요구대상 계좌가 없습니다' 노출 > [To-be] 금리 인하권 상품이 있을 경우 해당계좌노출 금리 인하 상품이 없을경우 ‘금리인하 요구대상 계좌가 없습니다' 미노출 ㅇ 배너 추가 : 내게 맞는 대출, 예금담보대출 배너 추가 | K14: 스타뱅킹2부_biz | Q14: KB스타뱅킹 금융상품몰 개편_회의록_요구사항분석_공통,수신,여신_20220511.docx
A15: Biz-003 | B15: 상품조회 | C15: 기능 | E15: 신규 | F15: 구축요건정의서 | G15: BFE-30003 | H15: 앱 이탈 방지 | I15: - IOS 대상폰 상품상제정보 조회 시 앱 외부로 이탈 Case 개선 ㅇ 펀드분석요약/수익률/포트폴리오 분석 관련정보 펀드상품 상세화면에서 iOS 모바일웹으로 이탈하는 오류수정 (펀드상품 상세화면에서 웹(제로인)으로 이탈) ㅇ [To-be] 펀드 상세항목 모두 이탈 없이 스타뱅킹 내에서 조회되도록 개발 ㅇ 보험: iOS에서 PDF뷰어(청약서, 상품설명서. 보험사 URL보내는 경우) 안열리는 현상 오류 수정 | K15: 스타뱅킹2부_biz | Q15: KB스타뱅킹 금융상품몰 개편_회의록_요구사항분석_공통,수신,여신_20220511.docx KB스타뱅킹 금융상품몰 개편_회의록_요구사항분석_보험_20220513.docx KB스타뱅킹 금융상품몰 개편_회의록_요구사항분석_스타뱅킹3부리뷰_20220525.docx
A16: Biz-003 | B16: 상품조회 | C16: 기능 | E16: 신규 | F16: 구축요건정의서 | G16: BFE-30004 | H16: 마케팅 요소 적용 | I16: - 금융상품몰 조회/상품가입 화면에서 개인화된 혜택 연계 제공(금융쿠폰 등) ※ 금융쿠폰 프로세스 구축 완료시 ㅇ 금융쿠폰 관련 기능은 별도 프로젝트 진행하며 개발 후 화면 적용 필요 (적용 관련 별도 협의 필요) : 조건부 수용 > 연관 이벤트 관련 어드민 기능 범위 : 수신, 여신, 펀드, 신탁, ISA, 청약, 외화예금, 퇴직연금, 보험, 골드투자통장 개별 상품 內 > 상품가입 완료 후 금융쿠폰 발급하도록 구현 - 연관 이벤트 조회 및 링크 기능 제공 ㅇ 보험사에서 진행중인 이벤트 있는 경우 스타뱅킹 금융상품 화면에 노출 필요 > 상품목록에서 해당 상품 영역에 '이벤트 진행중' 표시 > 해당상품 상세화면 내 이벤트 내용 안내화면 제공 | K16: 스타뱅킹2부_biz | Q16: KB스타뱅킹 금융상품몰 개편_회의록_요구사항분석_공통,수신,여신_20220511.docx KB스타뱅킹 금융상품몰 개편_회의록_요구사항분석_보험_20220513.docx | T16: 조건부수용
A17: Biz-004 | B17: 콘텐츠 | C17: 기능 | E17: 신규 | F17: 구축요건정의서 | G17: BFE-40001 | H17: 라이브 방송 | I17: - KB스타뱅킹 앱 내 라이브 방송 도입 ㅇ 라이브 방송 콘텐츠가 앱 내에서 재생(실시간 콘텐츠 있을 경우 금융상품몰 메인에 영역 표출) - 금융라이브 메뉴 신설 ㅇ 라이브 예고 안내, 지난 방송 보기, 댓글/후기 조회 ㅇ 라이브 방송 중 실시간 채팅, 연관상품 가입 연계 ㅇ 라이브 방송 참여자수/좋아요수 실시간 표시 - 대고객 서비스 정책 2원화 ㅇ 로그인 고객: 고객정보 연동(이벤트 참여 및 경품추첨대상) ㅇ 비로그인 고객: 라이브 동영상 조회 및 댓글참여 기능 - 라이브 알림 설정 기능(신규) (스뱅1부, 마케팅팀, 현업, IT, 개발팀 논의필요) : 6/10까지 확인 ㅇ Push 시스템 연동하여 알림 제공 ㅇ 라이브 예고편에 대하여 알림신청을 한 사용자 대상으로 push 발송 ㅇ 라이브 예고별 '알림신청' 메뉴를 통해 스타뱅킹 Push 알림 제공 ㅇ Push알림 신청 기능 신설 > 클릭 시 스타뱅킹 Push알림 동의 & '맞춤상품·혜택' 항목 동의가 필요하다는 안내 추가 (알림설정 메뉴 링크) ㅇ Push 발송시간 : 라이브방송 시작 3분 전 발송(유관부서 협의 필요) ㅇ Push 메시지 포함 내용 : 라이브방송 제목, 시작시간 ㅇ Push 메시지 클릭 시 : '금융라이브' 메뉴로 이동 - 지난 라이브 다시보기 기능 제공 ㅇ 화면 표출내용 : 썸네일 이미지, 라이브방송 제목, 누적시청자 수, 방송시간 표시 ㅇ 화면 클릭 시 : 동영상 재생(KB 내부 콘텐츠클라우드센터에 업로드된 파일 재생) ㅇ 영상 내 : 다시보기 영상 내의 이벤트 등이 종료되었음을 자막 또는 팝업 등으로 표시 ㅇ 지난 방송(다시보기)는 원본 동양상 그대로 제공 | K17: 스타뱅킹2부_biz | Q17: KB스타뱅킹 금융상품몰 개편_회의록_요구사항분석_공통,수신,여신_20220511.docx | T17: 6/10까지협의
A18: Biz-004 | B18: 콘텐츠 | C18: 기능 | E18: 신규 | F18: 구축요건정의서 | G18: BFE-40002 | H18: 라이브 방송 관리 | I18: - 라이브 방송 관련 관리 화면 신설 ㅇ 라이브 방송 예고, 지난방송 보기 업로드 등 관리 - 라이브 방송 관련 관리 화면 신설 ㅇ 라이브 방송 예고, 지난방송 보기 업로드 등 관리 - 라이브방송 편성 관리 ㅇ 라이브방송 리스트 등록/변경/조회(라이브방송 구분, 제목, 썸네일 이미지, 방송시간, 상세설명 등) ㅇ 리스트에서 라이브 방송 상태별(예고/지난방송 등)별, 기간별 조회(정렬) - 라이브방송 예고 관리 ㅇ 라이브방송 편성표 리스트에서 예고 표출여부 선택 ㅇ 방송 시작시간 이후에는 예고 미표출로 자동 전환 - 라이브방송 다시보기 관리 ㅇ 라이브방송 종료 시 동영상 파일 업로드(KB 콘텐츠클라우드센터에 업로드 후 어드민에 경로 입력) ㅇ 라이브방송 편성표 리스트에서 다시보기 표출여부 선택 | K18: 스타뱅킹2부_biz | Q18: KB스타뱅킹 금융상품몰 개편_회의록_요구사항분석_공통,수신,여신_20220511.docx
A19: Biz-004 | B19: 콘텐츠 | C19: 기능 | E19: 신규 | F19: 구축요건정의서 | G19: BFE-40003 | H19: 동영상 커스터마이징 고도화 | I19: - KB스타뱅킹 앱 내 동영상 활용 UX/UI 개선 ㅇ 동영상 크기/위치 조정 ㅇ 동영상 세로view 기능 제공 > 레이어팝업 및 Full 화면 모두 세로 뷰 제공 ㅇ 동영상 재생 시 고객이 조회/거래 중인 화면 동시 유지(현재화면에서 이탈하지 않고 동영상 조회 가능) ㅇ 동영상 시청 중 Time-out 되는 현상 개선 ㅇ 동영상 자막 On/Off 기능 제공(청각장애인 고려) > 자막은 화면 내부에 표출하는 방식으로 구현 > 스크린 리더기를 통해 자막내용 읽을 수 있도록 지원 (자막 Off 상태에서도 스크린리더기가 읽을 수 있도록 구현) ㅇ 동영상플레이어에서 레이어 팝업(PIP 기능) 형태로 띄우는 기능 제공 : 조건부 수용(메가존 플레이어 검토 후 범위 조정) > 거래와 동시에 동영상 재생 가능 > 레이어팝업 동영상 위치를 고객이 움직여서 변경(상단/하단) ㅇ 동영상 재생 영역과 거래화면 영역 분할 > 특정 화면의 경우 동영상과 거래화면 프레임 분리 지원 (화면 內 동영상 아이콘 클릭 시 프레임 분할) > 동영상은 상단에 재생하고, 하단 영역에서 거래 진행 가능 ㅇ 동영상 시청 중 타임아웃 현상 개선 > 동영상 재생 중에는 타임아웃 되지 않도록 구현 | K19: 스타뱅킹2부_biz | Q19: KB스타뱅킹 금융상품몰 개편_회의록_요구사항분석_공통,수신,여신_20220511.docx KB스타뱅킹 금융상품몰 개편_회의록_요구사항분석_신탁, ISA_20220512.docx | T19: 조건부수용
A20: Biz-004 | B20: 콘텐츠 | C20: 기능 | E20: 신규 | F20: 구축요건정의서 | G20: BFE-40004 | H20: 상품-콘텐츠 연계 강화 | I20: - 상품과 연관된 뉴스, 콘텐츠, 연관지수, 전문가 칼럼 등 유기적으로 연결 가능한 UI 구현 ㅇ 현재 운영되고 있는 콘텐츠의 링크 연결 | K20: 스타뱅킹2부_biz | Q20: KB스타뱅킹 금융상품몰 개편_회의록_요구사항분석_펀드_20220512.docx
A21: Biz-005 | B21: 상품가입 | C21: 기능 | E21: 신규 | F21: 구축요건정의서 | G21: BFE-50001 | H21: 공통 | I21: - 금융상품 가입 프로세스 슬림화 ㅇ 프로세스 단계/화면별 입력항목 축소, 입력항목 자동포커스(고객 클릭 최소화) ㅇ 상품가입 업무 범위 : 수신, 외화예금, 대출, 펀드, 신탁, ISA, 청약, 퇴직연금, 보험, 골드투자통장(은행-증권, 카드 제외) ㅇ 운용지시 업무 범위 : 퇴직연금(IRP), 연금저축펀드, 신탁형 ISA - 상품관련 조회 등 성능 개선을 위한 DB 튜닝 및 개선 - 금융상품 가입화면에 표준화된 UX/UI 적용 ㅇ 금융상품 별 상이한 가입 프로세스를 표준화하여 적용 ㅇ 필수 입력항목 등 연속 배치 등 UI 개선 ㅇ 입력 후 다음 입력항목에 대한 자동 포커싱 기능 ㅇ 연금저축펀드, 퇴직연금, 신탁형 ISA 등 유사 프로세스 표준화 - 약관/서식 확인 화면 개선 ㅇ 약관동의 UX/UI 표준화 적용(순서, 동의방식 등 표준화) ㅇ 화면 스크롤 필요한 경우 ‘스크롤 다운’ 기능 추가 ㅇ 실행버튼 하단에 고정(전부 읽지 않아도 확인 가능하도록 구성) ㅇ 계약서류 제공 방식 개선 및 통일 [As-is] 공란으로 Default [To-be] 이메일, 알림톡 등으로 Default 제공 ㅇ 고객 동의 및 이해 관련 체크박스 선택 최소화(관련 규제 위배사항 없도록) - ‘뒤로가기’ Navigation 오류 수정 - 투자성향 분석 화면 UX/UI 개선 ㅇ 대상화면 : 투자성향 분석, 투자성향 분석결과 확인, 구속성 확인 ㅇ 기존거래(펀드검색, 펀드가입 등)를 방해하지 않고 연결성 있게, 화면 내 과다한 정보/클릭요소 간소화하여 진입장벽 완화 - 프로젝트 기간 내 법률/제도 등 변경사항에 대한 대응개발 ※ ‘금융소비자보호법’ 비대면 가이드라인 발표(5월), 퇴직연금 디폴트옵션 시행(7월) - 대출서류 제출방식 추가 ㅇ [As-is] 사진촬영 ㅇ [To-be] 사진촬영 + 서류첨부(사진첩 내 사진만 선택) - 투자성향분석 As-Is 화면을 참고하여 UI 적용 ㅇ 인뱅 UI/UX 스타일과 통일성도 고려 - 투자성향 분석 개선 ㅇ(투자상품 공통) 투자성향 분석 화면 UX/UI 개선 ㅇ '①구속성 관련 안내+②금융취약소비자 확인+③투자성향 분석' 한 화면 또는 연속적으로 표출되도록 변경 ㅇ 구속성 및 금융취약소비자 확인은 全 상품 카테고리 합산 1일 1회 표출(기적용) ㅇ 기존거래(펀드검색, 펀드가입 등)를 방해하지 않고 연결성 있게, 화면 내 과다한 정보/클릭요소 간소화 하여 진입정벽 완화(하단팝업 활용, 한문항씩 진행 등 UX/UI검토) - 상품 신규 범위 ㅇ 메뉴>뱅킹>상품가입 ㅇ 신규에 준하는 일부 거래 포함 (대출: 기한연장, IRP/신탁형ISA/연금펀드: 운용지시) | K21: 스타뱅킹2부_biz | Q21: KB스타뱅킹 금융상품몰 개편_회의록_요구사항분석_공통,수신,여신_20220511.docx KB스타뱅킹 금융상품몰 개편_회의록_요구사항분석_신탁, ISA_20220512.docx
A22: Biz-005 | B22: 상품가입 | C22: 기능 | E22: 신규 | F22: 구축요건정의서 | G22: BFE-50002 | H22: 외화예금 | I22: - 원화예금 가입 프로세스 준용하여 가입 프로세스 변경 ㅇ 출금계좌와 동일한 비밀번호 설정 기능은 현재 AS-IS 적용 내용 그대로 반영 | K22: 스타뱅킹2부_biz | Q22: KB스타뱅킹 금융상품몰 개편_회의록_요구사항분석_공통,수신,여신_20220511.docx
A23: Biz-005 | B23: 상품가입 | C23: 기능 | E23: 신규 | F23: 구축요건정의서 | G23: BFE-50003 | H23: 펀드 | I23: - 집합투자증권 핵심(요약) 상품설명서 기능 개선 (펀드/퇴직연금) ㅇ 상품설명서 양식 OZ 형태로 틀만 제공하고 ‘펀드명, 위험등급’은 가변값으로 매핑하여 제공 : (스뱅3부와 별도 협의 : 6/3까지) ㅇ 다운로드 기능 추가 - 연금저축펀드의 모자계좌 가입방법 개선 ㅇ 모계좌, 자계좌 대체 표현 검토 ㅇ 운용비율 % 조정방법 UI 개선 ㅇ 모계좌 개설되지 않은 고객의 경우 모계좌/자계좌 선택 분기 없이 모계좌 신규가입으로 진행 - 골든라이프/라떼계좌 운용계획 확인 (WM상품부 확인 후 결저 : 6/3까지) - 상품정보 tab에서 제로인 데이터를 활용하여 제공 ㅇ 기간수익률 및 추이 그래프 > '기간별 추이 기준 : 1개월, 3개월, 6개월, 1년, 설정이후 ㅇ 기준가, 전일대비 기준가(등락률 포함), 기준가 추이 그래프 ㅇ 편입종목 Top 10 | K23: 스타뱅킹2부_biz | Q23: KB스타뱅킹 금융상품몰 개편_회의록_요구사항분석_펀드_20220512.docx KB스타뱅킹 금융상품몰 개편_회의록_요구사항분석_스타뱅킹3부리뷰_20220525.docx | T23: 6/3까지협의
A24: Biz-005 | B24: 상품가입 | C24: 기능 | E24: 신규 | F24: 구축요건정의서 | G24: BFE-50004 | H24: 신탁 | I24: - 영상통화 예약 후 ‘진행단계’ 확인 가능 화면으로 이동 ㅇ 상품가입 중 AS-IS 영상통화 후 화면이 멈춰있는데 이후 진행단계 화면으로 이동하여 가입이 계속되도록 수정 | K24: 스타뱅킹2부_biz | Q24: KB스타뱅킹 금융상품몰 개편_회의록_요구사항분석_신탁, ISA_20220512.docx
A25: Biz-005 | B25: 상품가입 | C25: 기능 | E25: 신규 | F25: 구축요건정의서 | G25: BFE-50005 | H25: 청약 | I25: - ‘청약거주지’ 항목 CRM주소 연동하여 디폴트로 제공 ㅇ 직접입력 통한 수정 가능 ㅇ '청약거주지' 직접입력 통한 수정 시 고객정보 변경 처리 - 신규가입 시 자동이체일이 약정납입일 이후인 경우 이체시작월을 당월로 세팅하여 신규 진행 ㅇ 신규가입 시 자동이체일 선택 기능 추가 ㅇ 선택한 이체일이 약정납입일 이후인 경우 이체시작월을 당월로 세팅 - 신규가입 완료 후 소득공제 신청거래 연동(소득공제 무주택확인서 제출 누락 방지) | K25: 스타뱅킹2부_biz | Q25: KB스타뱅킹 금융상품몰 개편_회의록_요구사항분석_공통,수신,여신_20220511.docx KB스타뱅킹 금융상품몰 개편_회의록_요구사항분석_청약_20220516.docx
A26: Biz-005 | B26: 상품가입 | C26: 기능 | E26: 신규 | F26: 구축요건정의서 | G26: BFE-50006 | H26: 보험 | I26: - '거래진행 중 오류발생 시 보험사에서 전송받은 에러메시지 고객안내는 AS-IS 그대로 적용 ㅇ 현재 공통오류 메시지가 상세 오류내용 식별 가능하도록 에러코드 세분화하여 맵핑됨 - 전 상품 보험가입 프로세스 표준화 ㅇ 해외납세의무 및 본인확인 절차 추가 - 입력항목 오류 시 오류메시지 표출 후 메인화면으로 이탈현상 개선사항 AS-IS 그대로 적용 ㅇ 화면이탈이 아닌, 해당 입력항목 수정입력 안내로 진행 ㅇ 보험 가입 프로세스에서 에러사항 확인 후 이전화면 아닌 홈으로 이동 | K26: 스타뱅킹2부_biz | Q26: KB스타뱅킹 금융상품몰 개편_회의록_요구사항분석_공통,수신,여신_20220511.docx KB스타뱅킹 금융상품몰 개편_회의록_요구사항분석_보험_20220513.docx
A27: Biz-006 | B27: 상품관리(어드민) | C27: 기능 | E27: 신규 | F27: 구축요건정의서 | G27: BFE-60001 | H27: 모바일용 관리화면 구축 | I27: - ‘모바일 상품 판매관련 관리어드민’ 구축(배치 포함) - KB스타뱅킹 금융상품몰 내 게시되는 상품 카테고리 및 라이브 방송 콘텐츠에 대한 관리 기능 개발 ㅇ 예·적금(외화포함), 대출, 펀드, 신탁(ISA포함), 청약, 퇴직연금, 방카슈랑스, 골드바/실버바 등(추후 확장 가능) ㅇ 신탁형ISA / 일임형ISA 어드민 신규 구축 ㅇ 퇴직연금 : 상품 검색시 IRP '껍데기' 표시를 위한 어드민 기능 개발(상품검색용) ㅇ 보험: 어드민 통한 추천상품 관리 기능 개발 '- 모바일 최적화된 관리화면 구성 ㅇ KB스타뱅킹 금융상품 화면 기준 입력항목/화면 구성 ㅇ 입력항목별 글자수(byte) 제한으로 텍스트 최소화 강제 ※ 펀드 위험등급 등 법적리스크와 관계된 주요정보는 상품팩토리에서 자동으로 불러와 리스크 최소화 ㅇ 모바일 상품 어드민 메뉴 신설(개발/스테이징/운영) > KB스타뱅킹에 표출되는 상품 정보를 별도로 관리하는 어드민 메뉴 별도 신설 (상품정보, 이미지, 동영상, 태그관리 등) > 금리/펀드 위험등급 등은 상품팩토리와 연동 > 결재 요청 시 통합어드민 항목 변경 확인하라는 안내 팝업 표출 ㅇ 펀드 관리자 > 기존 정보(팩토리/現어드민 내 항목&정보) 가져오기 * 동기화 영역(모든 항목 or 항목별) 선택 가능 > 제로인 Data 최대한 활용(수기 입력 최소화) > 상품군별/특징별 대세 선택값 디폴트 처리 > 클래스(동종상품 군) 구분 > 동일상품별(브랜드상품코드 기준) 공통 정보 사용 기본(1회만 등록) > 클래스 추가시 클래스별 차별 항목만 별도 입력 (같은 화면내 관리) > 대표 클래스 설정 기능 > 기준가 등록 ㄴ 기준가 등록여부 선택없이 자동 반영 (팩토리 별도 선택여부 단계 없이 무조건 적용중) > 대량 파일 업로드 기능 개발 > 다건상품정보 수정 엑셀업로드 기능 (현업 정책 검토 확인필요 : 6/3까지) | K27: 스타뱅킹2부_biz | Q27: KB스타뱅킹 금융상품몰 개편_회의록_요구사항분석_펀드_20220512.docx KB스타뱅킹 금융상품몰 개편_회의록_요구사항분석_퇴직연금_20220513.docx KB스타뱅킹 금융상품몰 개편_회의록_요구사항분석_어드민_220520.docx | T27: 6/3까지 협의
A28: Biz-006 | B28: 상품관리(어드민) | C28: 기능 | E28: 신규 | F28: 구축요건정의서 | G28: BFE-60002 | H28: 관리편의성 제고 | I28: - Html 에디터를 통해 일관성 있고 편리한 편집 기능 지원 : 조건부 수용 (HTML 에디터 외에 편리한 편집기능 방법 검토) (텍스트 줄맞춤, 들여쓰기/내어쓰기, 글머리/다단계 등) - 모바일 구현화면 미리보기 ㅇ 미리보기 기능은 개발환경의 제약안에서 구현 ㅇ 미리보기 화면은 상품등록 화면으로 한정 함. ㅇ 화면 미리보기의 경우 작업자 및 결재자 화면에서도 모두 구현되야 하며, 결재재 화면은 '결재함'을 의미한다. ㄴ 결재함 미리 보기 기능은 적용 여부는 개발 및 IT 기술검토 후 진행여부 확정 예정 (IT : 6/3까지) - 작성내용 임시저장/자동저장 기능 제공 ㅇ 임시저장 기능은 [임시저장] 버튼을 누르면 입력 데이터를 임시저장하도록 구현 ㅇ 임시저장한 경우 상품목록에 '임시저장' 상태로 표시, 해당 상품목록 클릭 시 저장 데이터를 불러오도록 구현 - 작성내용 즉시적용 또는 예약적용(날짜 및 시간) 선택 | K28: 스타뱅킹2부_biz | Q28: KB스타뱅킹 금융상품몰 개편_회의록_요구사항분석_어드민_220520.docx | T28: 조건부수용
A29: Biz-006 | B29: 상품관리(어드민) | C29: 기능 | E29: 신규 | F29: 구축요건정의서 | G29: BFE-60003 | H29: 결재관리 | I29: - 권한 및 결재 라인은 기존 어드민과 동일하게 부여(상품정보 관리, 게시 권한 부여된 담당자만 이용 가능) - 결재함 일괄결재 요청/일괄결재 기능 신설 ㅇ 다건의 작업내용 결재함에서 한 번에 결재요청 가능 ㅇ 다건의 작업목록 일괄결재 기능 제공 (현업 재검토 후 구현여부 및 범위 확정 예정 : 6/3까지) > 결재자는 결재함 내 결재 리스트에서 선택하여 결재 > 리스트 선택 시 어드민 수정(신규입력) 항목 표시 및 화면 미리보기 가능 - 결재자가 승인 대기중인 상태에서도 작업자가 작업 가능하도록 구현 | K29: 스타뱅킹2부_biz | Q29: KB스타뱅킹 금융상품몰 개편_회의록_요구사항분석_공통,수신,여신_20220511.docx KB스타뱅킹 금융상품몰 개편_회의록_요구사항분석_어드민_220520.docx | T29: 6/3까지 협의
A30: Biz-006 | B30: 상품관리(어드민) | C30: 기능 | E30: 신규 | F30: 구축요건정의서 | G30: BFE-60004 | H30: 상품태그 관리 | I30: - 태그(키워드) 관리 화면 신설 ㅇ 태그 등록/변경/삭제 > 현재는 각각 상품별로 태그를 수정하도록 되어 있는데 전체를 한번에 수정할 수 있는 기능 필요 ㅇ 태그 관리화면 설계시 상품 또는 카테고리 연결관련 고려하여 개발 ㅇ 태그별 이미지 등록/변경/삭제 ㅇ 등록된 태그와 금융상품 연결 > 각 상품상세 어드민에 등록된 태그 데이터 기준으로 태그별 상품목록 리스트 조회 > 태그별 상품 추가/삭제 가능(상품명/상품코드 조회를 통해 추가/삭제상품 선택) > 태그 관리화면에서 저장한 데이터를 각 상품 상세 태그 항목에 반영 (태그 관리메뉴 등록 정보와 상품상세 內 태그항목 동기화) ㅇ IRP, ISA, 연금저축펀드 등 상품 안에 상품이 들어있는 경우의 태그관리 방식 > 전체 통합검색(메인화면) 시에는 제도상품(껍데기) 상품 태그로 연결 > 상품 카테고리 내 검색 시에는 운용상품 內 태그로 연결 ㅇ 연관태그 등록 | K30: 스타뱅킹2부_biz | Q30: KB스타뱅킹 금융상품몰 개편_회의록_요구사항분석_어드민_220520.docx
A31: Biz-006 | B31: 상품관리(어드민) | C31: 기능 | E31: 신규 | F31: 구축요건정의서 | G31: BFE-60005 | H31: 상품 판매실적 조회 | I31: - KB스타뱅킹 상품별 조회/판매현황 조회 ㅇ 통합 어드민 내 통계화면을 두지 않는 정책에 따라 Mystar단말 또는 데이터시각화 화면에 구현 ㅇ Mystar단말 또는 데이터시각화에 전달할 수 있는 데이터 적재 구현 ㅇ 상품클릭수/가입자수/장바구니(관심상품), 상담 이어가기, 가입진행중 등록현황 조회 ㅇ 상품카테고리별 위 기준으로 정렬 기능 제공 ㅇ 상품별 가입금액/가입좌수 조회 | K31: 스타뱅킹2부_biz | Q31: KB스타뱅킹 금융상품몰 개편_회의록_요구사항분석_어드민_220520.docx
A32: Biz-006 | B32: 상품관리(어드민) | C32: 비기능 | E32: 신규 | F32: 구축요건정의서 | G32: BFE-60006 | H32: 직원용 가이드 | I32: - 화면 內 정보입력 항목 별로 안내문구/예시 등 포함하여 이해도 향상 - 어드민 기능 활용도 제고를 위한 사용자 가이드 제작 및 게시 ㅇ 각 화면별 가이드 파일 제공 | K32: 스타뱅킹2부_biz | Q32: KB스타뱅킹 금융상품몰 개편_회의록_요구사항분석_어드민_220520.docx

Sheet 요구사항명세서
A1: 업무 | B1: 구분 | C1: Biz요건ID | D1: Biz요건명 | E1: 요구사항구분 | F1: 생성단계 | G1: 상태구분 | H1: 출처 | I1: 요구사항ID | J1: 요구사항명 | K1: 기능/비기능요구사항 | L1: 사용자권한요구사항 | M1: 의뢰부서 | N1: 요구사항처리담당팀 | O1: 검토상태 | P1: 검토의견 | Q1: 변경요구사항ID | R1: 변경일 | S1: 근기문서 | T1: 구분
A2: 영업감사 | B2: RAS, C-RAS 위험지수 고도화 | C2: Biz-0001 | D2: RAS위험지수 정교화·고도화 | E2: 비기능 | F2: 요구사항정의 | G2: 신규 | H2: 구축요건정의서 | I2: MDD-00001 | J2: AI 위험모델을 연계한 RAS위험지수의 정교화 | K2: ⚪ AI위험평가결과 연계하여 해당 위험 지수를 참조 하는 형태로 구현 | M2: 감사부(영업감사) | O2: Accepted
A3: 영업감사 | B3: RAS, C-RAS 위험지수 고도화 | C3: Biz-0001 | D3: RAS위험지수 정교화·고도화 | E3: 기능 | F3: 요구사항정의 | G3: 신규 | H3: 구축요건정의서 | I3: MDD-00002 | J3: RAS신규항목(46개) 신설 및 기존항목 개선(상시감사 중복내용 통합 등) | K3: ⚪ RAS 모형 구성에 신규항목 4개 신설, 기존 감사자료 5개 를 추가하고 4개항목은 위험모형에서 제외 하여 위험모형 구축 | M3: 감사부(영업감사) | O3: Accepted
A4: 영업감사 | B4: RAS, C-RAS 위험지수 고도화 | C4: Biz-0001 | D4: RAS위험지수 정교화·고도화 | E4: 기능 | F4: 요구사항정의 | G4: 신규 | H4: 구축요건정의서 | I4: MDD-00003 | J4: 직원별 RAS 위험지수 모형 신설 | K4: ⚪ C-RAS1 위험모형, C-RAS2 위험모형를 이용한 직원별C-RAS3 위험모형 생성(현재 기능 유지) | M4: 감사부(영업감사) | O4: Accepted
A5: 영업감사 | B5: RAS, C-RAS 위험지수 고도화 | C5: Biz-0002 | D5: RAS전산평가 운영 확대 및 항목 신설 | E5: 비기능 | F5: 요구사항정의 | G5: 신규 | H5: 구축요건정의서 | I5: MDD-00004 | J5: RAS전산평가 운영 확대 및 항목 신설 | K5: ⚪ RAS 위험모형을 참조하여 고위험 지점을 추출하여 감사계획 수립에 적극 반영 | M5: 감사부(영업감사) | O5: Accepted
A6: 영업감사 | B6: RAS, C-RAS 위험지수 고도화 | C6: Biz-0003 | D6: C-RAS 정교화·분석기능 강화 | E6: 비기능 | F6: 요구사항정의 | G6: 신규 | H6: 구축요건정의서 | I6: MDD-00005 | J6: AI 위험모델을 연계한 모형 재구성 | K6: ⚪ C-RAS 위험모형과 AI위험평가결과 모형을 연계하여 해당 신규 위험모형을 생성하지 않고 AI위험평결과를 참조 하는 형태로 구현 | M6: 감사부(영업감사) | O6: Accepted
A7: 영업감사 | B7: RAS, C-RAS 위험지수 고도화 | C7: Biz-0004 | D7: 감사자료의 최신화·효율적 관리 | E7: 기능 | F7: 요구사항정의 | G7: 신규 | H7: 구축요건정의서 | I7: MDD-00006 | J7: 이상거래(고위험 업무) 항목 신설 및 형태별 분석 기능 | K7: ⚪ 감사자료 신규 37개 신설하여 감사자료의 확대로 이상거래(고위험 업무) 분석 기능 제공 | M7: 감사부(영업감사) | O7: Accepted | P7: 담당자 : 임경택 감사역 감사자료 10건 개발을 진행하나 해당 프로젝트외로 진행하기로 협의
A8: 영업감사 | B8: RAS, C-RAS 위험지수 고도화 | C8: Biz-0004 | D8: 감사자료의 최신화·효율적 관리 | E8: 기능 | F8: 요구사항정의 | G8: 신규 | H8: 구축요건정의서 | I8: MDD-00007 | J8: 부점별 감사자료 통합 검색기능 제공 | K8: ⚪ 감사자료 신규 37개도 부점별 검색 대상에 포함 되도록 기능 제공 | M8: 감사부(영업감사) | O8: Accepted | P8: 담당자 : 임경택 감사역 감사자료 10건 개발을 진행하나 해당 프로젝트외로 진행하기로 협의
A9: 영업감사 | B9: RAS, C-RAS 위험지수 고도화 | C9: Biz-0004 | D9: 감사자료의 최신화·효율적 관리 | E9: 비기능 | F9: 요구사항정의 | G9: 삭제 | H9: 구축요건정의서 | I9: MDD-00008 | J9: 감사마트DB 활용한 위험·중점 항목의 자동신설 기능 | K9: ⚪ 감사마트DB 활용한 위험·중점 항목의 자동신설 기능 | M9: 감사부(영업감사) | O9: Not Accepted | P9: 담당자: 김보영감사역 요구사항명세서 리뷰 시 삭제하기로 협의 사유 : 실제 영업감사는 감사마트를 활용하지 않으며 위험·중점 항목은 영업점위험평가 시뮬레이션 기능으로 대체하기로 함 | T9: 대면
A10: 영업감사 | B10: 감사계획 수립 자동화 | C10: Biz-0005 | D10: 위험수준 평가 및 대상 영업점 선정 자동화 | E10: 기능 | F10: 요구사항정의 | G10: 신규 | H10: 구축요건정의서 | I10: MDD-00009 | J10: 영업점별 위험수준 평가결과 조회 및 지표 산출 결과를 토대로 예정감사 등록하거나 신규 감사대상점 등록 | K10: ⚪ 위험평가항목 주기적으로 위험수준(RAS) 평가 후 결과를 업데이트 하여 표시 (p47) ⚪ 최초 1회 연간 평가결과를 기준으로 감사계획 자동 등록. 이후 업무 담당자 수정 시 변경가능 ⚪ 감사계획 등록 내역 중 수정이 필요한 대상은 선택 후 직접 수정 가능 (Ex.최근 위험평가 결과 고위험으로 분류된 대상 수정) ⚪ 변경사항 존재 시 등록버튼 클릭하여 내용 반영 (등록 확정 시 ‘감사계획 등록’ 화면과 연계되어 후속 프로세스 수행) ⚪ AI부점위험평가 모델 결과를 반영하여 위험부점여부, 평가점수, 순위, 위험구분 항목 표시 (AI부점위험평가결과 세부내역 협의 후 제공 여부) ⚪ 위험부점여부 클릭시 AI부점위험평가결과의 부점위험 세부항목 조회 팝업 기능 제공 (AI부점위험평가결과 세부내역 협의 후 제공 여부) | M10: 감사부(영업감사) | O10: Accepted | P10: 통합싱시감시시스템에서 AI 위험평가 데이터 연계 가능 시 AI부점 위험평가 결과 개발 예정 | T10: 대면
A11: 영업감사 | B11: 감사계획 수립 자동화 | C11: Biz-0006 | D11: 위험수준 평가 결과에 따라 주기별 감사대상점 추천 | E11: 기능 | F11: 요구사항정의 | G11: 신규 | H11: 구축요건정의서 | I11: MDD-00010 | J11: 직원 RAS위험평가 결과 조회 및 세부내역 확인 | K11: ⚪ 부점/영업그룹 단위 직원별 지수현황/순위 등을 조회할 수 있는 기능 제공 (p56) ⚪ 기준정보 데이터는 배치 수행으로 생성 - 실시간 조회는 되지않음(D-1 데이터) ⚪ 기준년월 달력컨트롤러로 교체 - 현재일자 출력, 비활성 처리 ⚪ 직원번호 검색 조건 추가 - 직원번호로 검색시 해당 직원의 모든 이력 출력 ⚪ 부점 검색 조건을 영업그룹/부점을 영업그룹/PG 로 변경 ⚪ 목록 출력 항목 추가 및 변경 (지역영업그룹 이후에 PG추가, 그룹내순위 다음에 PG별순위 추가, 부점내순위의 위치 PG별순위) ⚪ 위험평가 상세 조회 팝업 중 직원위험 유형분류는 AI직원평가결과 정보 추후 협의 후 결정 ⚪ 직원별 지수 조회는 RAS 정의에 따른 위험지수 결과로 표시 | M11: 감사부(영업감사) | O11: Accepted | T11: 대면
A12: 영업감사 | B12: 감사계획 수립 자동화 | C12: Biz-0006 | D12: 위험수준 평가 결과에 따라 주기별 감사대상점 추천 | E12: 기능 | F12: 요구사항정의 | G12: 신규 | H12: 구축요건정의서 | I12: MDD-00011 | J12: 영업점 위험항목별 수치 입력 및 관리 기능 제공 | K12: ⚪ 연간 위험항목 확정 기능 제공 (p49) - 값 조정에 의한 시뮬레이션은 확정 전까지만 가능 - 확정 이후는 변경하지 못하도록 확정 취소 권한에 대한 정의 필요 (감사부) - 위험산출비율 환산공식제공(감사부 및 시스템운영팀) ⚪ 위험수준 평가 시 항목별 가중치 수정기능 제공 (비율 변경 시 기 등록 내역 일괄 재산출 하도록 추가 기능 제공) ⚪ 항목점수 입력 및 관리를 위한 기능 제공 (p49) - 일괄등록 : 엑셀파일로 전체 영업점 리스트 일괄등록 할 수 있는 기능 제공 (기존 엑셀파일 활용) - 등록 : 영업점 개별 항목 입력 시 사용 - 수정 : 입력 된 내용 수정 시 사용 ⚪ 위험항목 추가 예정(정의 후 전달 예정 (p49) | M12: 감사부(영업감사) | O12: Accepted | T12: 대면
A13: 영업감사 | B13: 감사계획 수립 자동화 | C13: Biz-0007 | D13: 감사대상 영업점 확정시 감사계획 및 감사역 배정 자동화 | E13: 기능 | F13: 요구사항정의 | G13: 신규 | H13: 구축요건정의서 | I13: MDD-00012 | J13: 감사계획 등록 현황 조회 및 내용 수정 / (신규) 감사예정 영업점 계획 자동등록 기능 신설 | K13: ⚪ 영업점별 위험수준 평가결과‘ 화면에서 등록 확정된 대상은 별도의 입력 없이 자동으로 본 화면에서 조회 가능 (p50) ⚪ 배정감사역 추천등록 클릭 시 관련내용 Pop-up하여 지정 / 기존화면에서 배정 후 기 등록내역 표시 ⚪ 배정감사역 추천기준에 따른 일괄 자동등록 기능(감사계획 차수 기준) ⚪ 확정 클릭 시 감사계획 및 감사역 배정이 확정되어 기안문 작성 및 출력 프로세스로 이동 | M13: 감사부(영업감사) | O13: Accepted | T13: 대면
A14: 영업감사 | B14: 감사계획 수립 자동화 | C14: Biz-0007 | D14: 감사대상 영업점 확정시 감사계획 및 감사역 배정 자동화 | E14: 기능 | F14: 요구사항정의 | G14: 신규 | H14: 구축요건정의서 | I14: MDD-00013 | J14: 감사역 배정 정보를 확인하고 변경/등록 / (신규) 감사역 추천 배정 등록기능 신설 | K14: ⚪ 감사역 배정 추천조회 시 추천 배정결과가 해당 칸에 표시되며, 배정등록 시 확정되어 배정현황에 내용 업데이트 (p51) ⚪ 추천대상 영업점 선택 : 해당 차수에 포함된 영업점 전체 or 지정된 영업점만 반영 ⚪ 추천 우선기준 : 우선기준 선택 시 해당 기준에 맞는 알고리즘으로 감사역 배정 추천 - 추천감사역 알고리즘에 항목 추가 요청( 감사부에서 항목정의 후 전달 예정) ⚪ 배정인원 기준 선택 : 최소, 최대 인원 선택시 해당 인원기준에 맞춰 감사역 배정 진행 ⚪ ‘추천조회’ 버튼 클릭 시 감사역 배정 추천 기능 작동 > 2번 화면에 대상 표시 (p51) ⚪ ‘배정등록’ 버튼 클릭 시 추천결과에 표시된 내용이 배정확정 > 감사계획 등록 화면서 확정내용 표시 | M14: 감사부(영업감사) | O14: Accepted | T14: 대면
A15: 영업감사 | B15: 감사계획 수립 자동화 | C15: Biz-0007 | D15: 감사대상 영업점 확정시 감사계획 및 감사역 배정 자동화 | E15: 기능 | F15: 요구사항정의 | G15: 신규 | H15: 구축요건정의서 | I15: MDD-00014 | J15: 등록된 감사계획 관련 정보 조회 | K15: ⚪ 감사계획 등록 화면에서 확정 된 대상들만 본 화면에서 조회됨 (화면연계) (p52) ⚪ 입력 정보를 기반으로 기안문 양식이 자동생성 되며, 파일로 다운로드 가능 (감사계획차수 기준으로 생성) ※ 기안문 양식 별도 제공 필요(감사부) ⚪ 본부장 결재(수기) 완료 대상은 담당자가 계획 확정 처리하여 다음 프로세스로 진행 | M15: 감사부(영업감사) | O15: Accepted | T15: 대면
A16: 영업감사 | B16: 감사계획 수립 자동화 | C16: Biz-0007 | D16: 감사대상 영업점 확정시 감사계획 및 감사역 배정 자동화 | E16: 기능 | F16: 요구사항정의 | G16: 신규 | H16: 구축요건정의서 | I16: MDD-00015 | J16: 감사계획에 따른 감사건별 감사역 배정현황 조회 및 내용 수정 기능 제공 | K16: ⚪ 감사역 배정등록 시 동일한 감사기간 중 감사역이 이중 배정될 경우 팝업 안내 표시 (p53) ⚪ 감사역 배정등록 알림 팝업 표출 요건은 같은년도 같은 차수에 배정될경우 ⚪ 기 배정내용을 변경하시려면 확인버튼을 눌러주세요 문구 삭제 ⚪ 확인, 취소 버튼 삭제 및 닫기 버튼 추가 | M16: 감사부(영업감사) | O16: Accepted | T16: 대면
A17: 영업감사 | B17: 감사계획 수립 자동화 | C17: Biz-0007 | D17: 감사대상 영업점 확정시 감사계획 및 감사역 배정 자동화 | E17: 기능 | F17: 요구사항정의 | G17: 신규 | H17: 회의록 | I17: MDD-00016 | J17: 감사역 배정 시 활용되는 참고사항 등록·관리 | K17: ⚪ 목록 또는 팝업에서 기피등록건수 클릭시 기피대상 목록을 출력하는 기능 지원(p59) ⚪ 검색조건(Default:소속직원 전체) : 대상직원, 담당업무, 담당지역 ⚪ 조회결과 목록에서 특정 목록 더블클릭 시 상세보기 Pop-up - 기본정보(인사DB 연동) : 감사역, 직책, 감사부 전입일자, 업무경력 - 입력정보 : 순서, 담당업무, 담당지역 - 연계정보 : 기피등록건수 – 감사업무 기피대상 관리 및 감사배정현황(감사계획에서 담당 감사역 배정되었을 경우 해당 감사종류 표시) ⚪ 등록버튼 클릭 시 직원별 참고사항 입력 가능(입력 세부항목은 현업 확정 필요) ⚪ 조회결과 그리드의 "기피등록건수" 항목 클릭시기피대상 목록을 출력하는 기능 지원 | M17: 감사부(영업감사) | O17: Accepted | S17: 20241113_감사정보시스템 고도화 및 클라우드 전환 구축_영업감사_2.docx | T17: 대면
A18: 영업감사 | B18: 영업점 감사자료 포탈 | C18: Biz-0008 | D18: 영업점 현황과 위험수준 등을 종합적으로 제공 | E18: 기능 | F18: 요구사항정의 | G18: 신규 | H18: 구축요건정의서 | I18: MDD-00017 | J18: 임점 대상 부서의 현황 조회 | K18: ⚪ 부점정보 조회시 해당기간 PG장 정보 추가 (p42) | M18: 감사부(영업감사) | O18: Accepted | T18: 대면
A19: 영업감사 | B19: 영업점 감사자료 포탈 | C19: Biz-0008 | D19: 영업점 현황과 위험수준 등을 종합적으로 제공 | E19: 기능 | F19: 요구사항정의 | G19: 신규 | H19: 구축요건정의서 | I19: MDD-00018 | J19: 영업감사 진행 시 감사역들이 감사일보를 작성하고 관리하는 화면 | K19: ⚪ 알림기능 추가 > Daily 체크, 16시기준 감사일보 미작성(N) 감사역에게 workB를 통한 쪽지 알림 발송(p43) ⚪ 조회 결과 항목에 감사일지작성여부 추가 | M19: 감사부(영업감사) | O19: Accepted | T19: 대면
A20: 영업감사 | B20: 영업점 감사자료 포탈 | C20: Biz-0008 | D20: 영업점 현황과 위험수준 등을 종합적으로 제공 | E20: 기능 | F20: 요구사항정의 | G20: 신규 | H20: 구축요건정의서 | I20: MDD-00019 | J20: 감사 완료 후 감사결과 및 지적사항을 간략하게 기재 | K20: ⚪ 감사조서 내용 작성 시 자동 줄 맞추 기능은 현재 구현이 어려워서 다른 방안 강구 후 추가 협의 예정 (p44) - 감사조서 입력 항목에 세로로 위치 맞춤선 제공 제안 ⚪ 감사조서 작성 예시 전달 예정(표준화 방안 강구) | M20: 감사부(영업감사) | O20: Accepted | T20: 대면
A21: 영업감사 | B21: 영업점 감사자료 포탈 | C21: Biz-0008 | D21: 영업점 현황과 위험수준 등을 종합적으로 제공 | E21: 기능 | F21: 요구사항정의 | G21: 신규 | H21: 구축요건정의서 | I21: MDD-00020 | J21: 감사 완료 후 해당 영업점의 종합감사 결과 및 점검현황, 강평 등의 내용을 보고서 형태로 제공 | K21: ⚪ 부점별 위험 유형분석 결과요약 항목 AI위험분석결과 협의 후 전체 Layout 추가 협의(p45) ⚪ 감사 지적 현황 및 KPI감점 현황, RAS 전산평가 현황 등 기 적재 데이터를 활용하여 보고서 형식으로 화면 출력 ⚪ 조회 결과 항목 보고서 출력 기능 제공(보고서 양식 감사부에서 전달) ⚪ Layout 전달 예정 | M21: 감사부(영업감사) | O21: Accepted | T21: 대면
A22: 영업감사 | B22: 영업점 감사자료 포탈 | C22: Biz-0008 | D22: 영업점 현황과 위험수준 등을 종합적으로 제공 | E22: 비기능 | F22: 요구사항정의 | G22: 신규 | H22: 구축요건정의서 | I22: MDD-00021 | J22: 감사를 위한 항목별 부점 자료 조회 (내부통제 업무 관련) | K22: ⚪ 감사자료 출력 시 원천데이터 값 정합성 확보 ⚪ 영업감사 감사자료는 ASIS기능 유지(p46) | M22: 감사부(영업감사) | O22: Accepted | T22: 대면
A23: 영업감사 | B23: 영업점 감사자료 포탈 | C23: Biz-0008 | D23: 영업점 현황과 위험수준 등을 종합적으로 제공 | E23: 기능 | F23: 요구사항정의 | G23: 신규 | H23: 회의록 | I23: MDD-00022 | J23: 테마감사 대쉬보드 | K23: ⚪ 점검항목 1. 생활안정자금, 2.전세자금대출, 3. 신용대출 주택추가매수 항목 삭제 그외 항목 유지(p54) | M23: 감사부(영업감사) | O23: Accepted | S23: 20241113_감사정보시스템 고도화 및 클라우드 전환 구축_영업감사_2.docx | T23: 대면
A24: 영업감사 | B24: 영업점 감사자료 포탈 | C24: Biz-0008 | D24: 영업점 현황과 위험수준 등을 종합적으로 제공 | E24: 기능 | F24: 요구사항정의 | G24: 신규 | H24: 구축요건정의서 | I24: MDD-00023 | J24: 사전감사를 위한 부점현황과 점검항목, 특이정보, 참고사항 등 관련 정보를 종합제공 | K24: ⚪ 영업점 사전감사 시 필요한 주요정보들을 통합하여 한 화면에서 조회 가능하도록 변경(p58) ⚪ AI부점 위험평가 결과(Y/N)으로 받아온 결과를 화면에 표시(AI직원평가결과 정보 추후 협의 후 결정) ⚪ 조회결과 그리드 "감사종류" 항목의 테마감사의 팝업지원 필요 여부 확인(감사부) ⚪ 조회결과 그리드 "내부통제" 항목의 테마감사 이외의 항목 클릭시 감사결과보고서 팝업 출력 여부확인 ⚪ 테마감사일 경우 해당년도 해당 부점의 관련부점과 동일한 지점 리스트 출력 | M24: 감사부(영업감사) | O24: Accepted | P24: 통합싱시감시시스템에서 AI 위험평가 데이터 연계 가능 시 AI부점 위험평가 결과 개발 예정 | T24: 대면
A25: 영업감사 | B25: 영업점 감사자료 포탈 | C25: Biz-0008 | D25: 영업점 현황과 위험수준 등을 종합적으로 제공 | E25: 기능 | F25: 요구사항정의 | G25: 신규 | H25: 회의록 | I25: MDD-00024 | J25: 영업감사 현황을 확인할 수 있는 대시보드 | K25: ⚪ 영업감사 현황을 한번에 조회할 수 있는 대시보드 제공 (각 대시보드 종류별 상세내용은 후속페이지 참조)(p61, p62) ⚪ 위험평가별 현황 도표는 RAS기준(YYYY-1 기준) ⚪ 지역별 실시현황 도표는 화면에 맞추어 조정하며 클릭시 큰화면의 팝업 제공(영업감사> 메인의 감사진행 대시보드 기준으로 구현 ⚪ 업무별 현황 도표는 지적사항 기준으로 수신/여신 외의 기타 항목으로 출력 ⚪ 감사실시현황 p62 참조 ⚪ 지역별 실시현황은 기존 감사정보시스템에서 사용중인 지역지도 템플릿을 활용 기능 제공( p63 참조) ⚪ 감사지적현황 조회년도 기준으로 등록된 지적건수를 표시(p64 참조) ⚪ 지적 소분류*에 등록된 코드를 기준으로 업무별 지적내역을 표시(p65 참조) - 지적사항 다건 존재 시 스크롤로 표시하거나, 지적건수 기준 업무별 상위 Top5만 선별하여 표시하는 방식으로 구현 | M25: 감사부(영업감사) | O25: Accepted | S25: 20241113_감사정보시스템 고도화 및 클라우드 전환 구축_영업감사_2.docx | T25: 대면
A26: 영업감사 | B26: 기업여신 현황 관련 기능 개선 | C26: Biz-0009 | D26: 기업여신 현황 관련 기능 개선 | E26: 기능 | F26: 요구사항정의 | G26: 신규 | H26: 구축요건정의서 | I26: MDD-00025 | J26: 기존 감사자료(여신) 항목별 조회 자료를 ‘차주’ 단위에서 일괄로 조회할 수 있도록 기능제공 | K26: ⚪ 기업여신명세 화면 조회시 차주별로 선정된 모든 항목을 전반적으로 조회가능(P57) ⚪ 화면 조회 구분값은 현업담당자와 협의 후 확정 필요 ⚪ 리스트에 표시된 항목 클릭시 개별 세부내역 조회할 수 있도록 링크 (기존 ‘감사자료(여신)’ 각 항목 번호와 연계) ⚪ 항목 중 하나라도 조건에 해당하는 경우 목록에 표기됨 ⚪ 일 기준 판단기준이 있더라도 월중 한번의 조건에 만족하면 표기됨 ⚪ 기준정보 데이터는 배치 수행으로 생성 - 실시간 조회는 되지않음(D-1 데이터) ⚪ 차주는 관리점기준 | M26: 감사부(영업감사) | O26: Accepted | T26: 대면
A27: 영업감사 | B27: 영업감사 기타 | C27: Biz-0010 | D27: 기타 | E27: 기능 | F27: 요구사항정의 | G27: 신규 | H27: 회의록 | I27: MDD-00026 | J27: AI위험평가결과 직원위험조회 | K27: ⚪ 통합상시감사시스템에서 월별로 산출되는 AI직원위험평가 결과를 연계하여 조회하는 화면 (본 내용은 모듈2 AI위험평가결과 요건과 화면기능을 동일하게 승계함)(P175) ⚪ 조회하는 직원의 기본정보 표시 ⚪ 연계되는 정보를 화면에 표시 (조회형식/UI는 원천시스템과 동일하게 구현) ⚪ 감사지원 항목을 영업감사 항목으로 메뉴및 기능 재조정 정의(감사부) ⚪ AI 위험평가결과 연계 협의 하여 구현 여부 확인 ⚪ 영업감사로 위치 이동 | M27: 감사부(영업감사) | O27: Accepted | S27: 20241113_감사정보시스템 고도화 및 클라우드 전환 구축_영업감사_2.docx | T27: 대면
A28: 영업감사 | B28: 영업감사 기타 | C28: Biz-0010 | D28: 기타 | E28: 기능 | F28: 요구사항정의 | G28: 신규 | H28: 회의록 | I28: MDD-00027 | J28: AI위험평가결과 부점위험조회 | K28: ⚪ 통합상시감사시스템에서 월별로 산출되는 AI부점위험평가 결과를 연계하여 조회하는 화면 (본 내용은 모듈2 AI위험평가결과 요건과 화면기능을 동일하게 승계함)(P176) ⚪ 연계되는 정보를 화면에 표시 (조회형식/UI는 원천시스템과 동일하게 구현) ⚪ 감사지원 항목을 영업감사 항목으로 메뉴및 기능 재조정 정의(감사부)) ⚪ AI 위험평가결과 연계 협의 하여 구현 여부 확인 ⚪ 영업감사로 위치 이동 | M28: 감사부(영업감사) | O28: Accepted | S28: 20241113_감사정보시스템 고도화 및 클라우드 전환 구축_영업감사_2.docx | T28: 대면
A29: 영업감사 | B29: 영업감사 기타 | C29: Biz-0010 | D29: 기타 | E29: 기능 | F29: 요구사항정의 | G29: 신규 | H29: 회의록 | I29: MDD-00028 | J29: AI위험평가결과 부점위험조회(월별) | K29: ⚪ AI부점위험평가결과 연계하여 월말 기준 전체 부점 평가결과를 적재함 (월별 적재) (P177) - 적재대상 : 매월 말 AI부점위험평가 결과로 산출된 데이터 ⚪ 각 월별 AI부점위험평가를 표시하며, 고위험으로 평가된 항목은 붉은색으로 별도 표시 ⚪ 영업감사로 위치 이동 | M29: 감사부(영업감사) | O29: Accepted | S29: 20241113_감사정보시스템 고도화 및 클라우드 전환 구축_영업감사_2.docx | T29: 대면
A30: 영업감사 | B30: 영업감사 기타 | C30: Biz-0010 | D30: 기타 | E30: 기능 | F30: 요구사항정의 | G30: 신규 | H30: 회의록 | I30: MDD-00029 | J30: AI위험평가 결과 및 현황을 볼 수 있는 대시보드 기능 제공 | K30: ⚪ AI위험평가결과 연계하여 월말 기준 현황을 대시보드 형태로 제공(p178~p179) ⚪ 지역그룹별 위험직원 현황 – 지역그룹별 고위험직원으로 평가된 인력 수를 전월/당월로 분류하여 표시 ⚪ 위험직원 세부현황 – 평가월 기준 AI모델 분류값에 따른 세부내역을 그래프 형태로 표기 (세부항목은 모듈2 모델에 따라 변동 가능) ⚪ 지역그룹별 위험부점 현황 – AI부점위험평가 결과를 기준으로 각 지역그룹별 위험대상 ‘Y’인 부점개수를 집계 후 표시 (위험부점 숫자가 많은 그룹으로 순위 표시) ⚪ 조회년도의 전행 위험부점 개수를 월별로 집계하여 표시 (월별 변화율 별도 표시) ⚪ 본 화면은 미확정 요구사항으로 실제 구축단계에서 요건 확정하여 반영 필요 ⚪ 대시보드에서 지역그룹 단위 클릭시 별도 당월 위험부점으로 평가된 개별 부점을 조회할 수 있는 팝업창이 출력되며, 상세결과는 부점위험조회 화면으로 링크하여 상세내역을 직접 조회할 수 있도록 기능 제공 ⚪ 영업감사로 위치 이동 | M30: 감사부(영업감사) | O30: Accepted | S30: 20241113_감사정보시스템 고도화 및 클라우드 전환 구축_영업감사_2.docx | T30: 대면
A31: 영업감사 | B31: 영업감사 기타 | C31: Biz-0010 | D31: 기타 | E31: 기능 | F31: 요구사항정의 | G31: 신규 | H31: 회의록 | I31: MDD-00030 | J31: 부책감사 결과 등록 (심의 대상에 대한 세부 내용 및 관련 지적사항 입력) | K31: ⚪ 상시감사 지적사항으로 기 등록된 내용이 존재할 경우 관련 정보를 연계하여 화면에 표시(p55) - 상시감사>지적사항조회>영업점상시감사>교육사항 정보조회]의 계좌번호 같은 경우 ⚪ 기존 감사정보시스템에서 보유중인 내역 조회 추후 통합상시감사와 연계 ⚪ 내역조회 버튼 클릭시 출력되는 내용이 다양해 형식에 구애받지않고 내용출력(준법추진부와 협의 필요) | M31: 감사부(영업감사) | O31: Accepted | S31: 20241113_감사정보시스템 고도화 및 클라우드 전환 구축_영업감사_2.docx | T31: 대면
A32: 영업감사 | B32: 영업감사 기타 | C32: Biz-0010 | D32: 기타 | E32: 기능 | F32: 요구사항정의 | G32: 신규 | H32: 회의록 | I32: MDD-00031 | J32: 각 분기별 정기부책 실시 시 현황정보를 입력/조회 할 수 있는 기능 제공 | K32: ⚪ 정기부책 분기별 실시 내용을 등록하고 조회할 수 있는 기능 제공(p60) ⚪ (조회) 감사년도 및 분기 단위로 조건값을 지정하여 조회 가능 ⚪ 조회조건에 따라 표시된 항목별로 계좌수, 금액을 입력 할 수 있으며, 값 입력 후 저장을 눌러 데이터를 반영할 수 있음 - 계좌수(좌) 및 금액(백만원) 항목에 데이터 미입력 시 기본값 0 ⚪ 부책감사 현황(계좌수) 차트 제외 | M32: 감사부(영업감사) | O32: Accepted | S32: 20241113_감사정보시스템 고도화 및 클라우드 전환 구축_영업감사_2.docx | T32: 대면
A33: 본부감사 | B33: 디지털 내부통제 점검기능 강화 | C33: Biz-0011 | D33: 본부부서 디지털 내부통제 구축 | E33: 기능 | F33: 요구사항정의 | G33: 신규 | H33: 구축요건정의서 | I33: MDD-00032 | J33: 본부 디지털 내부통제 점검 체크리스트 항목 관리 | K33: ⚪ 본부 부서 디지털 내부통제 점검을 위해 기 선정된 주요 점검항목에 대한 현황을 조회하고 점검대상 존재 시 세부내역을 확인할 수 있도록 기능 제공(p88~p89) ⚪ 등록버튼은 시스템운영팀(IT)만 사용 가능하도록 권한 부여(점검항목 등록 후 데이터 연계 해야 하기 때문) | M33: 감사부(본점감사) | O33: Accepted | T33: 대면
A34: 본부감사 | B34: 디지털 내부통제 점검기능 강화 | C34: Biz-0011 | D34: 본부부서 디지털 내부통제 구축 | E34: 기능 | F34: 요구사항정의 | G34: 신규 | H34: 구축요건정의서 | I34: MDD-00033 | J34: 본부 디지털 내부통제 점검 체크리스트 항목별 세부 현황 조회 | K34: ⚪ 본부 부서 디지털 내부통제 점검을 위해 기 선정된 주요 점검항목에 대한 현황을 조회하고 점검대상 존재 시 세부내역을 확인할 수 있도록 기능 제공(p90~p91) ⚪ 조회조건에 점검항목 목록 추가 점검항목 선택시 검색조건 기준년월일을 점검주기에 따라 일 월로 변경 ⚪ 점검항목 상세보기를 팝업으로 구현 할지 아니면 점검항목별 메뉴로 별도 구현 할지 추후 정의하여 화면 기능 구현 | M34: 감사부(본점감사) | O34: Accepted | T34: 대면
A35: 본부감사 | B35: 디지털 내부통제 점검기능 강화 | C35: Biz-0011 | D35: 본부부서 디지털 내부통제 구축 | E35: 기능 | F35: 요구사항정의 | G35: 신규 | H35: 구축요건정의서 | I35: MDD-00034 | J35: 내부통제점검 체크리스트 항목별 현황조회 (법적서류 점검) | K35: ⚪ 법적서류 사무분담 지정현황 조회용 화면(p92) ⚪ 조회조건 – 부서 : 부점별 또는 전체부서 조회 가능, 조회기준일 : 현재일자 고정 ⚪ 조회기준 – 부점별 : 직원 사무분담내용에 ‘법적서류’가 포함된 직원을 표시 ⚪ 점검항목 상세보기를 팝업으로 구현 할지 아니면 점검항목별 메뉴로 별도 구현 할지 추후 정의하여 화면 기능 구현 | M35: 감사부(본점감사) | O35: Accepted | T35: 대면
A36: 본부감사 | B36: 디지털 내부통제 점검기능 강화 | C36: Biz-0011 | D36: 본부부서 디지털 내부통제 구축 | E36: 기능 | F36: 요구사항정의 | G36: 신규 | H36: 구축요건정의서 | I36: MDD-00035 | J36: 내부통제점검 체크리스트 항목별 현황조회 (법적서류 점검) | K36: ⚪ 법적서류 재고현황 조회용 화면(p93) ⚪ 조회조건 – 부서 : 부점별 또는 전체부서 조회 가능, 조회기준일 : 현재일자 고정 ⚪ 조회기준 – 부점별 : 인감서류 보유현황 표시 / 재고수량, 인수예정수량 존재시 클릭하여 세부내용 조회 가능 ⚪ 점검항목 상세보기를 팝업으로 구현 할지 아니면 점검항목별 메뉴로 별도 구현 할지 추후 정의하여 화면 기능 구현 | M36: 감사부(본점감사) | O36: Accepted | T36: 대면
A37: 본부감사 | B37: 디지털 내부통제 점검기능 강화 | C37: Biz-0011 | D37: 본부부서 디지털 내부통제 구축 | E37: 기능 | F37: 요구사항정의 | G37: 신규 | H37: 구축요건정의서 | I37: MDD-00036 | J37: 내부통제점검 체크리스트 항목별 현황조회 (법적서류 점검) | K37: ⚪ 부점별 법적서류 교부/폐기 현황 조회용 화면(p94) ⚪ 조회조건 – 부서 : 부점별 또는 전체부서 조회 가능, 조회기준일 : 현재일자 고정, 조회구분 : 전체/교부/일반폐기 ⚪ 조회기준 – 부점별 : 법적서류 보유현황 상세내역을 표기 (경영정보시스템 데이터 연계) ⚪ 점검항목 상세보기를 팝업으로 구현 할지 아니면 점검항목별 메뉴로 별도 구현 할지 추후 정의하여 화면 기능 구현 | M37: 감사부(본점감사) | O37: Accepted | T37: 대면
A38: 본부감사 | B38: 디지털 내부통제 점검기능 강화 | C38: Biz-0011 | D38: 본부부서 디지털 내부통제 구축 | E38: 기능 | F38: 요구사항정의 | G38: 신규 | H38: 구축요건정의서 | I38: MDD-00037 | J38: 내부통제점검 체크리스트 항목별 현황조회 (인장날인 점검) | K38: ⚪ 인장날인 사무분담 지정현황 조회용 화면(p95) ⚪ 조회조건 – 부서 : 부점별 또는 전체부서 조회 가능, 조회기준일 : 현재일자 고정) ⚪ 조회기준 – 부점별 : 직원 사무분담내용에 ‘인장관리’, ‘인장입회’가 포함된 직원을 표시 (부서별 등록현황에 따라 표시정보 중복 가능) ⚪ 점검항목 상세보기를 팝업으로 구현 할지 아니면 점검항목별 메뉴로 별도 구현 할지 추후 정의하여 화면 기능 구현 | M38: 감사부(본점감사) | O38: Accepted | T38: 대면
A39: 본부감사 | B39: 디지털 내부통제 점검기능 강화 | C39: Biz-0011 | D39: 본부부서 디지털 내부통제 구축 | E39: 기능 | F39: 요구사항정의 | G39: 신규 | H39: 구축요건정의서 | I39: MDD-00038 | J39: 내부통제점검 체크리스트 항목별 현황조회 (인장날인 점검) | K39: ⚪ 인장날인 절차 미준수 현황 조회용 화면(p96) ⚪ 조회조건 – 부서 : 부점별 또는 전체부서 조회 가능, 조회기준일 : 현재일자 고정 ⚪ 점검항목 상세보기를 팝업으로 구현 할지 아니면 점검항목별 메뉴로 별도 구현 할지 추후 정의하여 화면 기능 구현 | M39: 감사부(본점감사) | O39: Accepted | T39: 대면
A40: 본부감사 | B40: 디지털 내부통제 점검기능 강화 | C40: Biz-0011 | D40: 본부부서 디지털 내부통제 구축 | E40: 기능 | F40: 요구사항정의 | G40: 신규 | H40: 구축요건정의서 | I40: MDD-00039 | J40: 내부통제점검 체크리스트 항목별 현황조회 (인장날인 점검) | K40: ⚪ 중요인장 날인명세(담보용) 조회용 화면(p97) ⚪ 조회조건 – 부서 : 부점별 또는 전체부서 조회 가능, 조회기준일 : 현재일자 고정 ⚪ 점검항목 상세보기를 팝업으로 구현 할지 아니면 점검항목별 메뉴로 별도 구현 할지 추후 정의하여 화면 기능 구현 | M40: 감사부(본점감사) | O40: Accepted | T40: 대면
...

Sheet 피벗_SUMMAY(현황)
A3: 개수 : 업무 | B3: 승인상태
A4: 업무 | B4: Accepted | C4: Conditional Accepted | D4: Not Accepted | E4: 총합계
A5: 영업감사 | B5: 24 | C5: 6 | D5: 1 | E5: 31
A6: 본부감사 | B6: 47 | C6: 1 | D6: 2 | E6: 50
A7: 일상감사 | B7: 4 | E7: 4
A8: 상시감사 | B8: 10 | D8: 5 | E8: 15
A9: 심의/조사 | B9: 12 | D9: 1 | E9: 13
A10: 감사지원 | B10: 13 | D10: 4 | E10: 17
A11: 공통 | B11: 11 | E11: 11
A12: 총합계 | B12: 121 | C12: 7 | D12: 13 | E12: 141

Sheet 피벗_SUMMARY(기능_비기능)
A3: 개수 : 요구사항구분 | C3: 상태/검토구분
C4: 신규 | E4: 삭제 | F4: 총합계
A5: 기능/비기능 | B5: 업무 | C5: Accepted | D5: Conditional Accepted | E5: Not Accepted
A6: 기능 | B6: 영업감사 | C6: 20 | D6: 6 | F6: 26
B7: 본부감사 | C7: 47 | D7: 1 | E7: 2 | F7: 50
B8: 상시감사 | C8: 10 | E8: 5 | F8: 15
B9: 일상감사 | C9: 4 | F9: 4
B10: 심의/조사 | C10: 12 | E10: 1 | F10: 13
B11: 감사지원 | C11: 13 | E11: 4 | F11: 17
B12: 공통 | C12: 8 | F12: 8
A13: 기능 요약 | C13: 114 | D13: 7 | E13: 12 | F13: 133
A14: 비기능 | B14: 영업감사 | C14: 4 | E14: 1 | F14: 5
B15: 공통 | C15: 3 | F15: 3
A16: 비기능 요약 | C16: 7 | E16: 1 | F16: 8
A17: 총합계 | C17: 121 | D17: 7 | E17: 13 | F17: 141
B31: (

Sheet 작성가이드

Sheet ※(요약)확정현황
B1: < 전체현황 >
K2: 실시간 | M2: <전주대비 증감>
B3: 개수 : 요구사항ID | C3: 검토상태 | I3: 총합계 (S = A+B+C+D+E+F) | J3: 진행율 (A+B+C+E+F)/S | K3: 수용율 (A+B)/S | M3: 검토상태 | Q3: 총합계 (S = A+B+C+D) | R3: 진행율 (A+B+C)/S | S3: 수용율 (A+B)/S
B4: 행 레이블 | C4: 승인(개발가능) (A) | D4: 조건부승인(일부개발가능) (B) | E4: 거부(삭제) (C ) | F4: 거부-이관 ( E) | G4: 거부-통폐합 (F) | H4: 미정 (D) | M4: 승인(개발가능) (A) | N4: 조건부승인(일부개발가능) (B) | O4: 거부(개발불가) (C ) | P4: 미정 (D)
B5: UXUI | C5: =COUNTIFS(#REF!,'※(요약)확정현황'!B5,#REF!,"승인") -> #REF! | D5: =COUNTIFS(#REF!,'※(요약)확정현황'!B5,#REF!,"조건부승인") -> #REF! | E5: =COUNTIFS(#REF!,'※(요약)확정현황'!B5,#REF!,"거부") -> #REF! | F5: =COUNTIFS(#REF!,'※(요약)확정현황'!B5,#REF!,"거부-이관") -> #REF! | G5: =COUNTIFS(#REF!,'※(요약)확정현황'!B5,#REF!,"거부-통폐합") -> #REF! | H5: =COUNTIFS(#REF!,'※(요약)확정현황'!B5,#REF!,"") -> #REF! | I5: =SUM(C5:H5) -> #REF! | J5: =(C5+D5+E5+F5+G5)/I5 -> #REF! | K5: =(C5+D5)/I5 -> #REF! | M5: =C5-C16 -> #REF! | N5: =D5-D16 -> #REF! | O5: =E5-E16 -> #REF! | P5: =H5-H16 -> #REF! | Q5: =I5-I16 -> #REF! | R5: =J5-J16 -> #REF! | S5: =K5-K16 -> #REF!
B6: 응용개발-공통뱅킹 | C6: =COUNTIFS(#REF!,'※(요약)확정현황'!B6,#REF!,"승인") -> #REF! | D6: =COUNTIFS(#REF!,'※(요약)확정현황'!B6,#REF!,"조건부승인") -> #REF! | E6: =COUNTIFS(#REF!,'※(요약)확정현황'!B6,#REF!,"거부") -> #REF! | F6: =COUNTIFS(#REF!,'※(요약)확정현황'!B6,#REF!,"거부-이관") -> #REF! | G6: =COUNTIFS(#REF!,'※(요약)확정현황'!B6,#REF!,"거부-통폐합") -> #REF! | H6: =COUNTIFS(#REF!,'※(요약)확정현황'!B6,#REF!,"") -> #REF! | I6: =SUM(C6:H6) -> #REF! | J6: =(C6+D6+E6+F6+G6)/I6 -> #REF! | K6: =(C6+D6)/I6 -> #REF! | M6: =C6-C17 -> #REF! | N6: =D6-D17 -> #REF! | O6: =E6-E17 -> #REF! | P6: =H6-H17 -> #REF! | Q6: =I6-I17 -> #REF! | R6: =J6-J17 -> #REF! | S6: =K6-K17 -> #REF!
B7: 응용개발-대응개발 | C7: =COUNTIFS(#REF!,'※(요약)확정현황'!B7,#REF!,"승인") -> #REF! | D7: =COUNTIFS(#REF!,'※(요약)확정현황'!B7,#REF!,"조건부승인") -> #REF! | E7: =COUNTIFS(#REF!,'※(요약)확정현황'!B7,#REF!,"거부") -> #REF! | F7: =COUNTIFS(#REF!,'※(요약)확정현황'!B7,#REF!,"거부-이관") -> #REF! | G7: =COUNTIFS(#REF!,'※(요약)확정현황'!B7,#REF!,"거부-통폐합") -> #REF! | H7: =COUNTIFS(#REF!,'※(요약)확정현황'!B7,#REF!,"") -> #REF! | I7: =SUM(C7:H7) -> #REF! | J7: =(C7+D7+E7+F7+G7)/I7 -> #REF! | K7: =(C7+D7)/I7 -> #REF! | M7: =C7-C18 -> #REF! | N7: =D7-D18 -> #REF! | O7: =E7-E18 -> #REF! | P7: =H7-H18 -> #REF! | Q7: =I7-I18 -> #REF! | R7: =J7-J18 -> #REF! | S7: =K7-K18 -> #REF!
B8: 응용개발-모바일 | C8: =COUNTIFS(#REF!,'※(요약)확정현황'!B8,#REF!,"승인") -> #REF! | D8: =COUNTIFS(#REF!,'※(요약)확정현황'!B8,#REF!,"조건부승인") -> #REF! | E8: =COUNTIFS(#REF!,'※(요약)확정현황'!B8,#REF!,"거부") -> #REF! | F8: =COUNTIFS(#REF!,'※(요약)확정현황'!B8,#REF!,"거부-이관") -> #REF! | G8: =COUNTIFS(#REF!,'※(요약)확정현황'!B8,#REF!,"거부-통폐합") -> #REF! | H8: =COUNTIFS(#REF!,'※(요약)확정현황'!B8,#REF!,"") -> #REF! | I8: =SUM(C8:H8) -> #REF! | J8: =(C8+D8+E8+F8+G8)/I8 -> #REF! | K8: =(C8+D8)/I8 -> #REF! | M8: =C8-C19 -> #REF! | N8: =D8-D19 -> #REF! | O8: =E8-E19 -> #REF! | P8: =H8-H19 -> #REF! | Q8: =I8-I19 -> #REF! | R8: =J8-J19 -> #REF! | S8: =K8-K19 -> #REF!
B9: 인프라 | C9: =COUNTIFS(#REF!,'※(요약)확정현황'!B9,#REF!,"승인") -> #REF! | D9: =COUNTIFS(#REF!,'※(요약)확정현황'!B9,#REF!,"조건부승인") -> #REF! | E9: =COUNTIFS(#REF!,'※(요약)확정현황'!B9,#REF!,"거부") -> #REF! | F9: =COUNTIFS(#REF!,'※(요약)확정현황'!B9,#REF!,"거부-이관") -> #REF! | G9: =COUNTIFS(#REF!,'※(요약)확정현황'!B9,#REF!,"거부-통폐합") -> #REF! | H9: =COUNTIFS(#REF!,'※(요약)확정현황'!B9,#REF!,"") -> #REF! | I9: =SUM(C9:H9) -> #REF! | J9: =(C9+D9+E9+F9+G9)/I9 -> #REF! | K9: =(C9+D9)/I9 -> #REF! | M9: =C9-C20 -> #REF! | N9: =D9-D20 -> #REF! | O9: =E9-E20 -> #REF! | P9: =H9-H20 -> #REF! | Q9: =I9-I20 -> #REF! | R9: =J9-J20 -> #REF! | S9: =K9-K20 -> #REF!
B10: 전문위원 | C10: =COUNTIFS(#REF!,'※(요약)확정현황'!B10,#REF!,"승인") -> #REF! | D10: =COUNTIFS(#REF!,'※(요약)확정현황'!B10,#REF!,"조건부승인") -> #REF! | E10: =COUNTIFS(#REF!,'※(요약)확정현황'!B10,#REF!,"거부") -> #REF! | F10: =COUNTIFS(#REF!,'※(요약)확정현황'!B10,#REF!,"거부-이관") -> #REF! | G10: =COUNTIFS(#REF!,'※(요약)확정현황'!B10,#REF!,"거부-통폐합") -> #REF! | H10: =COUNTIFS(#REF!,'※(요약)확정현황'!B10,#REF!,"") -> #REF! | I10: =SUM(C10:H10) -> #REF! | J10: =(C10+D10+E10+F10+G10)/I10 -> #REF! | K10: =(C10+D10)/I10 -> #REF!
B11: 총합계 | C11: =SUM(C5:C10) -> #REF! | D11: =SUM(D5:D10) -> #REF! | E11: =SUM(E5:E10) -> #REF! | F11: =SUM(F5:F10) -> #REF! | G11: =SUM(G5:G10) -> #REF! | H11: =SUM(H5:H10) -> #REF! | I11: =SUM(I5:I10) -> #REF! | J11: =(C11+D11+E11+F11+G11)/I11 -> #REF! | K11: =(C11+D11)/I11 -> #REF! | M11: =SUM(M5:M9) -> #REF! | N11: =SUM(N5:N9) -> #REF! | O11: =SUM(O5:O9) -> #REF! | P11: =SUM(P5:P9) -> #REF! | Q11: =SUM(Q5:Q9) -> #REF! | R11: =J11-J21 -> #REF! | S11: =K11-K21 -> #REF!
B13: <전주-9주차> | K13: 2/17 18시기준
B14: 개수 : 요구사항ID | C14: 검토상태 | I14: 총합계 (S = A+B+C+D+E) | J14: 진행율 (A+B+C+E)/S | K14: 수용율 (A+B)/S
B15: 행 레이블 | C15: 승인(개발가능) (A) | D15: 조건부승인(일부개발가능) (B) | E15: 거부(삭제) (C ) | F15: 거부-이관 ( E) | H15: 미정 (D)
B16: UXUI | C16: 72 | D16: 33 | E16: 28 | F16: 0 | H16: 71 | I16: 201 | J16: 0.65 | K16: 0.51
B17: 응용개발-공통뱅킹 | C17: 4 | D17: 0 | E17: 0 | F17: 0 | H17: 1 | I17: 5 | J17: 0.8 | K17: 0.8
B18: 응용개발-대응개발 | C18: 0 | D18: 0 | E18: 0 | F18: 0 | H18: 1 | I18: 1 | J18: 0 | K18: 0
B19: 응용개발-모바일 | C19: 4 | D19: 0 | E19: 0 | F19: 0 | H19: 0 | I19: 4 | J19: 1 | K19: 1
B20: 인프라 | C20: 26 | D20: 2 | E20: 0 | F20: 0 | H20: 1 | I20: 29 | J20: 0.97 | K20: 0.97
B21: 총합계 | C21: 106 | D21: 35 | E21: 28 | F21: 0 | H21: 74 | I21: 240 | J21: 0.7 | K21: 0.58

Sheet (참고)요구사항ID채번
B1: ** 요구사항ID채번시 업무별 아래규칙을 준수바랍니다. ** 관리위치 : \200.프로젝트표준\240.개발_양식템플릿\01.요구사항정의\NEW KB스타뱅킹구축-요구사항ID 채번규칙.xlsx
B2: 팀명 | C2: 업무대분류 | D2: 업무세분류 | E2: 요구사항ID범위 | F2: 비고 | H2: 팀명
B3: 전문위원 | C3: - | D3: - | E3: AP코드-10000 | F3: 요구사항ID증가는 10단위로 반영(추후 누락분 반영을 위한 최소간격 유지) | H3: 전문위원
B4: 인프라 | C4: - | D4: - | E4: AP코드-90000 | H4: 인프라
B5: 공통 | C5: 공통 | D5: 로그인/인증 | E5: AP코드-21000 | H5: 공통
B6: 공통 | D6: 계열사/외부연계 | E6: AP코드-22000 | H6: 뱅킹
B7: 공통 | D7: 기타 공통 | E7: AP코드-23000 | H7: 상품/외환
B8: 공통 | D8: 인증센터 | E8: AP코드-24000 | H8: 자산관리
B9: 공통 | D9: UX전문위원 | E9: AP코드-25000 | H9: 모바일
B10: 공통 | D10: 디자인 | E10: AP코드-26000
B11: 공통 | D11: 퍼블리싱 | E11: AP코드-27000
B12: 뱅킹 | C12: 조회 | D12: - | E12: AP코드-30000
B13: 뱅킹 | C13: 이체 | D13: - | E13: AP코드-31000
B14: 공통 | C14: 관리 | D14: - | E14: AP코드-40000
B15: 공통 | C15: 인증/보안 | D15: - | E15: AP코드-41000
B16: 뱅킹 | C16: 공과금 | D16: - | E16: AP코드-42000
B17: 상품/외환 | C17: 외환 | D17: - | E17: AP코드-50000
B18: 자산관리 | C18: 금융서비스 | D18: - | E18: AP코드-60000
B19: 자산관리 | D19: 자산관리 | E19: AP코드-61000
B20: 상품/외환 | C20: 상품 | D20: 상품라운지 | E20: AP코드-70000
B21: 상품/외환 | D21: 예금 | E21: AP코드-71000
B22: 상품/외환 | D22: 대출 | E22: AP코드-72000
B23: 상품/외환 | D23: 퇴직연금 | E23: AP코드-73000
B24: 상품/외환 | D24: 신탁/ISA | E24: AP코드-74000
B25: 상품/외환 | D25: 보험/공제 | E25: AP코드-75000
B26: 상품/외환 | D26: 펀드 | E26: AP코드-76000
B27: 상품/외환 | D27: 골드/주화 | E27: AP코드-77000
B28: 상품/외환 | D28: 청약/채권 | E28: AP코드-78000
B29: 상품/외환 | D29: 카드 | E29: AP코드-79000
B30: 공통 | C30: 고객센터 | E30: AP코드-80000
B31: 공통 | C31: 영업점 | E31: AP코드-81000
B32: 공통 | C32: 이벤트/마케팅 | E32: AP코드-82000
B33: 공통 | C33: 설정 | E33: AP코드-83000
B34: 공통 | C34: 알림함 | E34: AP코드-84000
B35: 모바일 | C35: 모바일웹 | E35: AP코드-85000
B36: 모바일 | C36: 다국어 | E36: AP코드-86000
B37: 모바일 | C37: 태블릿 | E37: AP코드-87000
B38: 모바일 | C38: 위젯 | E38: AP코드-88000

Sheet 감리제출용
A1: Biz요건ID | B1: Biz요건명 | C1: 요구사항구분 | D1: 생성단계 | E1: 상태구분 | F1: 출처 | G1: 요구사항ID | H1: 요구사항명 | I1: 기능/비기능요구사항 | J1: 사용자권한요구사항 | K1: 의뢰부서 | L1: 요구사항처리담당팀 | M1: 검토 상태 | N1: 검토의견 | O1: 변경요구사항ID | P1: 변경일 | Q1: 근기문서 | R1: 수행사 담당자 | S1: 업무상세 | T1: Tech그룹협의필요 대상여부(Y/N) | U1: Tech그룹 유관부서명 | V1: Tech그룹 담당자 | W1: 비고 | X1: IT 담당자 | Y1: ACE담당자 | Z1: 요건협의 미진여부(Y/N) | AA1: IT요건 세부협의 대상 | AB1: Native 협의 대상 | AH1: 요구사항추적표담당자 | AI1: 특이사항 | AJ1: 조건부승인 확정예정일자(YYYY-MM-DD)
A2: Biz-038 | B2: 로그인수단 | C2: 기능 | D2: 요구사항정의 | E2: 신규 | F2: 구축요건정의서 | G2: BFE-21000 | H2: 로그인방식 축소 | I2: - 로그인방식 개수 축소 ㅇ 모바일인증서(기본값, 지문&Face ID/패턴 지원), 공인인증서(지문/암호입력), ID/PW · 금융결제원 인증서 도입에 따른 적용 [0209] '- KB모바일인증서를 사용할수 없는 경우 ㅇ 금융인증서, 공동인증서를 먼저 노출할 수 있는 기능 필요(김민지D) | K2: 개인뱅킹플랫폼부 | L2: UXUI | M2: 승인 | Q2: 20210111_UXUI(공통)_회의록_로그인,인증 2차 요건협의_ver1.0.docx | R2: 이채우 | S2: 공통(로그인/인증) | T2: N | U2: N | X2: 김원용 수석/이상호 팀장/이정윤 대리/전동화 대리 | Y2: 박형준 차장 권장우 대리 | AB2: ● | AH2: 신재현이사
A3: Biz-013 | B3: ARS 추가인증 | C3: 기능 | D3: 요구사항정의 | E3: 신규 | F3: 구축요건정의서 | G3: BFE-21010 | H3: ARS인증 안내 멘트 시각화 | I3: - ARS인증 안내 멘트 시각화 ㅇ ARS 안내멘트 시각화 제시를 통한 사용자 편의성 제공 - ARS 인증 통화 시 안내창 팝업 표시 ㅇ ARS인증 통화 수신 시 인증번호 안내 창(팝업)을 휴대폰 화면 상단 표시 [0205] - 리브에 있는 interface 참고해서 진행. | K3: 개인뱅킹플랫폼부 | L3: UXUI | M3: 승인 | Q3: 20210205_UXUI(공통)_회의록_요구사항분석_로그인.인증.기타_ver1.0.docx | R3: 이채우 | S3: 공통(로그인/인증) | T3: N | U3: N | X3: 김원용 수석 | Y3: 박형준 차장 권장우 대리 | AB3: ● | AH3: 신재현이사
A4: Biz-039 | B4: 자동로그인 | C4: 기능 | D4: 요구사항정의 | E4: 신규 | F4: 구축요건정의서 | G4: BFE-21020 | H4: 자동로그인 추가 | I4: - 자동로그인 기능 신설 ㅇ 등록조건 · 휴대폰 기기 잠금설정 필수 (잠금설정 해제 시 자동로그인 자동해제) · 1인 1기기 정책(새 기기에 등록되면 기존 기기 자동로그인은 자동 해제) · 모바일인증서 사용자만 가능 · 자동로그인 설정기간 지정하여 재설정하도록 유도 (ex. 6개월 단위로 자동로그인 갱신) ㅇ 프로세스: 이용약관 동의 > 추가본인인증 (ARS/휴대폰 본인인증) > 가입완료 - 자동로그인 ON/OFF 설정 페이지(로그인 화면, 설정 메뉴) 제공 ㅇ 자동로그인 ON 설정시 모바일인증서 결제비밀번호(6자리) 1회 입력 후 가능 ㅇ 복수 아이디 사용자의 경우 사전 안내 공지 - 자동로그인 설정 시 소액 간편이체서비스 자동 가입 ㅇ 1일 이체 한도 : 이체시 1일 누적 200만원 이하 소액이체만 가능 ※ 現 ‘계좌뷰’ 기능 삭제에 따른 고객 불편 해소 검토사항 - 자동로그인 실패시 예외 처리 방법 논의 필요(앱을 종료할 경우 사용불가 상태에 빠짐) - 앱성능 향상을 위해 앱위변조 검증 단계 간소화에 대한 자동로그인 적용방법 논의 필요.(자동로그인에 한정된 사항은 아님) | K4: 개인뱅킹플랫폼부 | L4: UXUI | M4: 승인 | Q4: 20210111_UXUI(공통)_회의록_로그인,인증 2차 요건협의_ver1.0.docx | R4: 이채우 | S4: 공통(로그인/인증) | T4: N | U4: 정보보안플랫폼부 | V4: 이민욱 차장 | X4: 이상호 팀장/이정윤 대리/전동화 대리 | Y4: 박형준 차장 권장우 대리 | AB4: ● | AH4: 신재현이사
A5: Biz-014 | B5: 추가인증 방식 공통화 | C5: 기능 | D5: 요구사항정의 | E5: 신규 | F5: 구축요건정의서 | G5: BFE-21030 | H5: 거래별 추가인증 방식 공통화 | I5: - 추가인증 방식에 대한 각 거래별 공통화 적용(공통화면 사용토록 개선) ------------------------------------------------------ - 휴대폰 본인인증 공통화면 사용(단, 업무 프로세스상 별도 예외 필요시 제외) - 연락처 본인인증(AOS), ARS인증, 해외출국사실확인 3종 셋트를 기본으로 각 거래에서 필요한 방식 공통 적용 | K5: 개인뱅킹플랫폼부 | L5: UXUI | M5: 승인 | Q5: 20210205_UXUI(공통)_회의록_요구사항분석_로그인.인증.기타_ver1.0.docx | R5: 이채우 | S5: 공통(로그인/인증) | T5: N | U5: N | X5: 이상호 팀장/이정윤 대리/전동화 대리 | Y5: 박형준 차장 권장우 대리 | AH5: 권영순부장
A6: Biz-015 | B6: 연락처 본인인증 | C6: 기능 | D6: 요구사항정의 | E6: 신규 | F6: 구축요건정의서 | G6: BFE-21040 | H6: 연락처 본인인증 단계 간소화 | I6: - 연락처본인인증 단계 간소화 (AOS) ㅇ 추가인증단계 연락처 본인인증 선택시 시스템으로 검증작업 후 결과만 노출 · CRM 정보와 휴대폰 번호가 일치하는 경우, 전화번호 검증 팝업 없이 추가인증 진행 · 추가인증 팝업 화면 진입시 CRM정보와 휴대폰 번호일치여부 체크후 불일치 하는 경우 ‘연락처본인인증’ 버튼 미노출 --------------------------------- - CRM정보와 연락처 본인인증 번호가 일치하는 경우 추가인증은 자동인증 처리 방식으로 제공 | K6: 개인뱅킹플랫폼부 | L6: UXUI | M6: 승인 | Q6: 20210205_UXUI(공통)_회의록_요구사항분석_로그인.인증.기타_ver1.0.docx | R6: 이채우 | S6: 공통(로그인/인증) | T6: N | U6: N | X6: 이상호 팀장/이정윤 대리/전동화 대리 | Y6: 박형준 차장 권장우 대리 | AH6: 권영순부장
A7: Biz-049 | B7: 모바일 인증서 모듈화 | C7: 기능 | D7: 요구사항정의 | E7: 신규 | F7: 구축요건정의서 | G7: BFE-21050 | H7: 스타뱅킹 外 앱에서 모바일인증호출 | I7: - 스타뱅킹 外 앱에서 모바일인증서 호출시 App-in-App 형태 구동 (Native 앱 구조 변경사항) ㅇ 프로세스 변경 · As-is : 타 앱에서 모바일인증서 호출 시 App to App 형태로 스타뱅킹이 전면 활성화되어 연결 속도 저하 · To-be : 타 앱에서 모바일인증서 호출 시 App-in-App 형태로 구현 (스타뱅킹 자체는 로딩없이 비활성화하고 인증 화면만 반키패드 형태 노출) ㅇ 모바일인증서 연계 적용되는 타 앱/계열사 연동 개발 필요(마이머니, 리브, KB손해보험 등) - 당행 및 계열사 다른 앱에서 KB모바일인증서 구동 시 빠르고 자연스러운 인증화면 전환 ([목표] 카카오페이인증 보다 신속하게) [02/22] - 인트로화면 노출 후 모바일인증서 로그인 화면으로 진행되게 구현 - 연동로그인 화면이 현재 하이브리드 화면으로 구현되어 있음. -> TOBE에서는 네이티브 전환 검토(변경수정사항 발생시 앱배포 이슈 있음) -> 연계 화면별로 적용 가능여부 추가 검토 후 진행 | K7: 개인뱅킹플랫폼부 | L7: UXUI | M7: 승인 | Q7: 20210111_UXUI(공통)_회의록_로그인,인증 2차 요건협의_ver1.0.docx | R7: 박준규 | S7: 네이티브 | T7: N | U7: N | X7: 김원용 수석 | Y7: 박형준 차장 권장우 대리 | AB7: ● | AH7: 신재현이사
A8: Biz-040 | B8: 인증 화면 분리 | C8: 기능 | D8: 요구사항정의 | E8: 신규 | F8: 회의록 | G8: BFE-21070 | H8: 인증화면 분리 | I8: 공인인증서 로그인 시, 로그인 화면과 인증 화면 분리 필요(김민지 대리) ㄴ 두 화면이 중첩되므로 인해 생기는 이슈 다수 발생(ex. 공인인증서 인증서 로그인 → 대출 신청 → 로그인) | K8: 개인뱅킹플랫폼부 | L8: UXUI | M8: 승인 | Q8: 20210205_UXUI(공통)_회의록_요구사항분석_로그인.인증.기타_ver1.0.docx | R8: 이채우 | S8: 공통(로그인/인증) | T8: N | U8: N | X8: 이상호 팀장/이정윤 대리/전동화 대리 | Y8: 박형준 차장 권장우 대리 | AH8: 권영순부장
A9: Biz-205 | B9: 스타샷 기능 분리 | C9: 기능 | D9: 요구사항정의 | E9: 신규 | F9: 구축요건정의서 | G9: BFE-21080 | H9: 사고신고/해제, 증명서 발급-보안매체 | I9: - 스타샷과 변경/신고/재발급 각 동일 기능 메뉴 통폐합 ㅇ 등록/변경 : 중요증서 이용등록, 계좌비밀번호 변경, 출금 등록, 자동이체 등록/변경 등 (① 보안카드 등록, ② OTP등록, ③ 스마트 OTP등록, ④ 타기관 OTP등록, ⑤ OTP발급신청, ⑥ 계좌비밀번호 변경, ⑦ 계좌비밀번호 분실변경, ⑧ 이체한도 조회/변경, ⑨ 출금계좌 등록/해지, ⑩ 스마트창구출금 등록, ⑪ 스마트창구출금 해제, ⑫ 스마트ATM출금 등록, ⑬ 스마트ATM출금 해제, ⑭ 계좌간자동이체) ㅇ 사고신고/해제 : 보안카드, OTP, 통장/인감, 계좌 비밀번호, 인터넷뱅킹 등 사고신고 및 해제 (① 분실신고 제공, ② 보안카드 분실신고 해제, ③ 보안카드 일련번호 해제, ④ 보안카드 비밀번호 해제, ⑤ OTP분실신고, ⑥ OTP분실신고 해제, ⑦ OTP 비밀번호 해제, ⑧ 인터넷뱅킹 이용제한 해제, ⑨ 전화승인비밀번호 오류 해제, ⑩ 통장인감 분실신고, ⑪ 통장/인감 분실신고 해제, ⑫ 계좌비밀번호 변경, ⑬ 계좌비밀번호오류 해제) ㅇ 재발급 : ① 보안카드 재발급, ② OTP재발급, ③ 통장 재발급 '- 스타샷과 변경/신고/재발급 각 동일 기능 메뉴 통폐합 ㅇ 등록/변경 : 중요증서 이용등록, 계좌비밀번호 변경, 출금 등록, 자동이체 등록/변경 등 (① 보안카드 등록, ② OTP등록, ③ 스마트 OTP등록, ④ 타기관 OTP등록, ⑤ OTP발급신청, ⑥ 계좌비밀번호 변경, ⑦ 계좌비밀번호 분실변경, ⑧ 이체한도 조회/변경, ⑨ 출금계좌 등록/해지, ⑩ 스마트창구출금 등록, ⑪ 스마트창구출금 해제, ⑫ 스마트ATM출금 등록, ⑬ 스마트ATM출금 해제, ⑭ 계좌간자동이체) ㅇ 사고신고/해제 : 보안카드, OTP, 통장/인감, 계좌 비밀번호, 인터넷뱅킹 등 사고신고 및 해제 (① 분실신고 제공, ② 보안카드 분실신고 해제, ③ 보안카드 일련번호 해제, ④ 보안카드 비밀번호 해제, ⑤ OTP분실신고, ⑥ OTP분실신고 해제, ⑦ OTP 비밀번호 해제, ⑧ 인터넷뱅킹 이용제한 해제, ⑨ 전화승인비밀번호 오류 해제, ⑩ 통장인감 분실신고, ⑪ 통장/인감 분실신고 해제, ⑫ 계좌비밀번호 변경, ⑬ 계좌비밀번호오류 해제) ㅇ 재발급 : ① 보안카드 재발급, ② OTP재발급, ③ 통장 재발급 | K9: 개인뱅킹플랫폼부 | L9: UXUI | M9: 조건부승인 | N9: [0504]조건부승인->승인 변경 IA 및 현업 요건으로 최종 반영 | Q9: 20210122_UIUX(관리)_회의록_1차 요구사항분석_ver1.0.docx | R9: 이채우 | S9: 보안/인증 | T9: N | X9: 조형준 대리 | Y9: 이재민 대리 권장우 대리 | AH9: 권영순부장 | AJ9: 44320
A10: Biz-048 | B10: KB Pay | C10: 기능 | D10: 요구사항정의 | E10: 삭제 | F10: 회의록 | G10: BFE-22000 | H10: 앱 → 계열사 연계 | I10: - KB국민카드 Pay 서비스 연계(방식에 대한 추후 논의 필요) ㅇ 이용방식 : 충전식 선불카드 ㅇ 이용가능고객 : 만 14 이상 ~ 19세 고객만 사용 가능(은행 회원/비회원 모두 사용가능) ㅇ 회원가입 : 휴대폰본인확인 > 약관동의 > 회원가입 ㅇ 회원원장 : KB pay 회원가입을 전제(로그인 처리를 위한 은행 내부 별도 원장 체계 구축 필요) ㅇ 로그인 : KB pay 전용 로그인 화면 필요 ㅇ 서비스범위 : 잔액충전, 결재(KB pay 전 가맹점/온오프라인 포함), 송금(연락처) [확장형 플랫폼 논의사항] 위 요건인 선불카드, 회원가입 등은 제외 전용 로그인 화면 필요 제외(확정 필요) 최종 보고 결과 확인 필요. | K10: 개인뱅킹플랫폼부 | L10: UXUI | M10: 거부 | N10: [0420]BFE-17030과 중복 | Q10: 20201229_UXUI(공통)_회의록_로그인,인증,관리,메인, 계열사외부연계 관련 2차 요건협의_ver1.0.docx | R10: 이채우 | S10: 계열사/외부연계 | T10: N | U10: N | X10: 권희영 차장 | Y10: 조세형 과장 이재민 대리 | AH10: 권영순부장 | AI10: [0420]
A11: Biz-051 | B11: 계열사연계 | C11: 기능 | D11: 요구사항정의 | E11: 신규 | F11: 구축요건정의서 | G11: BFE-22010 | H11: KB APP 및 계열사 APP안내 페이지 개선 | I11: - KB APP 및 계열사 APP안내 페이지 개선 ㅇ APP 설치 유무에 따른 아이콘 표시 및 각 APP 클릭시 연동 되도록 구성 (SSO가능한 앱에 限) · 설치 대상 앱(계열사/당행) 아이콘 안내 및 설치여부 상태 시각적 구분 | K11: 개인뱅킹플랫폼부 | L11: UXUI | M11: 승인 | R11: 박준규 | S11: 계열사/외부연계 | T11: N | U11: N | X11: 권희영 차장 | Y11: 조세형 과장 이재민 대리 | AB11: ● | AH11: 권영순부장
A12: Biz-172 | B12: 알면 도움되는 스타뱅킹 서비스 | C12: 기능 | D12: 요구사항정의 | E12: 신규 | F12: 구축요건정의서 | G12: BFE-23000 | H12: 스타뱅킹 관련 안내 페이지 제공 | I12: - 스타뱅킹 관련 안내 페이지 제공 ㅇ KB 스타드림 서비스, 스타샷 촬영납부, 포인트리 골드전환, 스마트서류제출, 개인대출 금리인하요구권, 맞춤환전, 외환ATM 위치조회, 펀드자동환매서비스, 펀드정기지급서비스, 배달 콘텐츠, 증명서 발급, 국세/지방세 납부(As-is 이체 하위에 있던 내용) | K12: 개인뱅킹플랫폼부 | L12: UXUI | M12: 승인 | R12: 김효은 | S12: UI/UX | T12: N | U12: N | X12: N/A | Y12: 황인태 차장 정광환 대리 | AH12: 정찬민이사
A13: Biz-012 | B13: 비대면 실명확인 | C13: 기능 | D13: 요구사항정의 | E13: 신규 | F13: 구축요건정의서 | G13: BFE-23010 | H13: 비대면 실명확인 프로세스 개선 | I13: - 비대면 실명확인 절차 간소화 ㅇ 로그인 후 비대면 실명확인 수행한 경우, 동일 세션 內 추가 실명확인 대상 (2+1 거래)실행 생략 · 인증서 발급 등 거래에 따라 차등 적용가능 [0205] - 적용 제외 대상 업무는 개인뱅킹플랫폼부에서 상세화면 설계 중 업무단위로 확인, - 개별 업무에서 진행할 수 있게 공통개발팀에서 가이드 제공, 실제 적용은 해당 업무 개발팀에서 진행. | K13: 개인뱅킹플랫폼부 | L13: UXUI | M13: 승인 | Q13: 20210205_UXUI(공통)_회의록_요구사항분석_로그인.인증.기타_ver1.0.docx | R13: 박준규 | S13: 공통(기타) | T13: N | U13: N | X13: 이상호 팀장/이정윤 대리/전동화 대리 | Y13: 박형준 차장 권장우 대리 | AH13: 권영순부장
A14: Biz-016 | B14: CDD/EDD | C14: 기능 | D14: 요구사항정의 | E14: 신규 | F14: 구축요건정의서 | G14: BFE-23020 | H14: CDD/EDD | I14: - CDD/EDD메뉴 접근 후 ‘고객확인 등록’ 거래 진행시 ID로그인/비로그인 방식 추가 ㅇ '2+1 인증방식(휴대폰 본인인증, 신분증촬영, 본인명의 계좌검증)'을 통한 본인인증절차를 고려할 때 ID/PW, 비로그인시에도 가능하도록 개선 -------------------------- 고객 입력 주소 검증에 대한 부분 확인 필요(자금세탁방지부) [0205] - 프로세스 수정, 보완 건으로 진행 - 공통업무 요건이 아니며 개인뱅킹 업무 요건으로 진행. | K14: 자금세탁방지부 | L14: UXUI | M14: 승인 | Q14: 20210205_UXUI(공통)_회의록_요구사항분석_로그인.인증.기타_ver1.0.docx | R14: 이채우 | S14: 공통(기타) | T14: N | U14: N | X14: 이상호 팀장/이정윤 대리/전동화 대리 | Y14: 박형준 차장 권장우 대리 | AH14: 권영순부장
A15: Biz-017 | B15: 거래내역 저장 | C15: 기능 | D15: 요구사항정의 | E15: 신규 | F15: 구축요건정의서 | G15: BFE-23030 | H15: 거래내역 저장 | I15: - 계좌 거래내역 XLS/PDF 형식파일 저장 서비스 제공 ㅇ 입출금, 예·적금, 신탁, 펀드, 대출, 외화(보통/정기)예금, 퇴직연금 등 - 거래내역 E-mail 전송 서비스 제공 [0216] - 이메일전송서비스로 요건 보완 후 검토 진행 중 - 발송 용량(1만 바이트)에 따라 일반 메일 방식과 첨부파일 방식으로 구분 필요 - 대상 거래 확정 후 거래별 용량 산정, 정보보안 검토 등 진행 예정. [02/22] - 권장우 대리 쪽지 회신 내용. 1. 거래내역조회 상품별 테이블 현황 캡쳐자료 공유드립니다. [첨부파일 참조] (보험/공제는 확인전) 2. 마스킹여부: 현재도 마스킹처리되지 않음. 신한 쏠도 마스킹여부에 대해 고객 선택(필수X). 신한처럼 선택 가능하도록 제공 검토 3. 템플릿: 템플릿은 인터넷뱅킹 형식을 활용할 수 있는지 검토 4. 개발방식: 전문방식으로 개발하고 1만바이트 초과 시에는 조형준대리님쪽에서 체크하여 안내메시지 노출 후 이메일 발송 정상처리 (안내메일 예시: 거래내역 이메일 발송은 최대 XX건까지 가능합니다. 조회하신 모든 거래내역이 발송되지 않을 수 있습니다.) | K15: 개인뱅킹플랫폼부 | L15: UXUI | M15: 승인 | Q15: 20210216_UXUI(조회)_회의록_요구사항분석_거래내역이메일발송_ver1.0.docx | R15: 박준규 | S15: 조회 | T15: N | U15: 데이터분석플랫폼부 | V15: 김홍윤 수석 | X15: 조형준 대리 | Y15: 박형준 차장 권장우 대리 | AH15: 이정환부장
A16: Biz-018 | B16: 영수증 이미지 저장 | C16: 기능 | D16: 요구사항정의 | E16: 삭제 | F16: 구축요건정의서 | G16: BFE-23040 | H16: 영수증 이미지 저장 | I16: - 앱 內 영수증 이미지 저장/조회 기능 신규제공 ㅇ 대면 MyStar단말 영수증조회(10-70-002)거래 기능 앱 內 신설 · 단말(10-70-002) 거래 모두 해당 · 영업점 직원이 단말에서 종이영수증 발급 여부 선택 가능하도록 개선 ㅇ 비대면거래 내역(이체확인증) 기능 제공 --------------------------------- - 대면거래에 해당하는 영수증만 조회 - 외국환계산서, 무통장입금확인증, 예금 이자계산서(예금 해지시 등), 수수료 영수증(OTP/통장/제증명발급), 자동화기기(CD/ATM) 인출/송금 명세표, 자동이체신청 확인서(고객용), 전자금융거래신청확인서(고객용), 입출금통지서비스신청확인서, 집합투자증권추가매입/환매신청확인서 --------------------------------- 포함 대상 거래 확정 필요 - 조회 조건(최대 조회 기간 포함) - Push 알림 기능 필요 여부 [0205] - 대상 영수증에 대해 단말 거래에서 발급여부 설정을 위해서는 계정계 협의 등 추가 확인 필요. - 증빙자료로서 영수증 제공을 위해서는 워터마크 등 별도 기능 추가 필요. - 영수증 발급 대상 거래 및 개발범위 등 추가 확인 후 재협의. [0219] - 워터마크는 법률 사항과 관계 없음. 워터마크 출력은 가능. - 영수증 출력항목에 대해서는 세부 확인 필요. (각 현업 개별 협의, 확인 필요) [02/22] - 네이티브 개발요건 없음. | K16: 개인뱅킹플랫폼부 | L16: UXUI | M16: 거부 | N16: [0420]BFE-23041과 중복 [0222] 테크그룹 화상회의 영수증 발급이 아닌, 대면 납부 수수료 내역 조회 요건으로 진행 가능 확인. 조회 대상 거래가 모두 적재되고 있는지 확인 후 필요시 담당 IT 확인 후 추가 협의 진행. 조회 이미지 저장 요건 자체는 가능한 것으로 확인. 관련 단말거래 확인결과 1070-002 거래는 대면에서 발급한 영수증만 재발행하는 것으로 요구사항 불충족 10700-003 거래는 대면에서 발생한 수수료 내역을 조회하는 것으로 확인되어 해당 거래를 이용한 별도의 신규 요건으로 진행키로 협의함. | Q16: 20210205_UXUI(공통)_회의록_요구사항분석_로그인.인증.기타_ver1.0.docx | R16: 박준규 | S16: 공통(기타) | T16: Y | U16: 코어뱅킹1플랫폼부 | V16: 이향림 과장 | X16: N/A | Y16: 박형준 차장 권장우 대리 | AH16: 권영순부장 | AI16: [0420]
A17: Biz-019 | B17: 서식 view | C17: 기능 | D17: 요구사항정의 | E17: 신규 | F17: 구축요건정의서 | G17: BFE-23050 | H17: 서식 view | I17: - 약관/설명서/동의서 등 각종 서식 문서 Viewer 방식으로 변경 -------------------------------------------- - html 약관 사용 없이, 통합어드민 서식/약관자료실 파일 연동 처리로 모두 변경 -------------------------------------------- [0205] - ASIS 적용사항 TOBE에 적용. - 적용시 각 업무개발팀에서 진행. | K17: 개인뱅킹플랫폼부 | L17: UXUI | M17: 승인 | Q17: 20210205_UXUI(공통)_회의록_요구사항분석_로그인.인증.기타_ver1.0.docx | R17: 박준규 | S17: 공통(기타) | T17: N | U17: N | X17: 이상호 팀장/이정윤 대리/전동화 대리 | Y17: 박형준 차장 권장우 대리 | AH17: 권영순부장
A18: Biz-020 | B18: 공통 태그 라이브러리 | C18: 기능 | D18: 요구사항정의 | E18: 신규 | F18: 구축요건정의서 | G18: BFE-23060 | H18: 공통 태그 라이브러리 | I18: - 공통 태그 라이브러리 유형화 ㅇ 주소입력, 권유직원, 보안매체, 추가인증 등 요소별 태그 유형화하여 수정 및 운영 용이성 증대 [0205] - ASIS 영향도 없게 하고, 스타뱅킹 중 개인뱅킹 업무에만 적용 가능하게 구현. | K18: 개인뱅킹플랫폼부 | L18: UXUI | M18: 승인 | Q18: 20201224_UIUX(공통)_회의록_기타공통_1차 요구사항분석_ver1.0.docx | R18: 박준규 | S18: 공통(기타) | T18: N | U18: N | X18: 이상호 팀장/이정윤 대리/전동화 대리 | Y18: 박형준 차장 권장우 대리 | AH18: 권영순부장
A19: Biz-043 | B19: DIY | C19: 기능 | D19: 요구사항정의 | E19: 신규 | F19: 구축요건정의서 | G19: BFE-23070 | H19: DIY | I19: - 고객 Needs에 따른 DIY 기능 제공 (필요시 기존 스타뱅킹 거래, New스타뱅킹 사용) ㅇ 전체메뉴의 개인별 설정(필수 노출 메뉴는 수정 불가) ㅇ My메뉴, 생활금융 콘텐츠, 목표설정 등 화면에 설정 기능 제공 | K19: 개인뱅킹플랫폼부 | L19: UXUI | M19: 승인 | Q19: 20210205_UXUI(공통)_회의록_요구사항분석_로그인.인증.기타_ver1.0.docx | R19: 박준규 | S19: 개인화 | T19: N | U19: N | X19: 권희영 차장 | Y19: 조세형 과장 | AH19: 권영순부장
A20: Biz-050 | B20: 상담연계 | C20: 기능 | D20: 요구사항정의 | E20: 삭제 | F20: 구축요건정의서 | G20: BFE-23080 | H20: 서비스 불가시 상담거래 자동 연계 | I20: - 비대면 처리 불가시 상담거래 자동 연계 ㅇ 비대면 업무처리가 불가한 경우(오류메시지 등) 에러 표시 후 챗봇 상담연계 · 오류 메시지 2회 노출시 챗봇 화면으로 이동 ㅇ 비대면 업무처리 中 영업점 필수 업무 선택시 ‘스마트예약상담’ 거래연동 및 필요서류 안내 ----------------------------- - 에러메시지 內 상담전화가 표시되어 연결하는 경우 콜봇(SSO)이나 챗봇으로 연계 ----------------------------- | K20: 개인뱅킹플랫폼부 | L20: UXUI | M20: 거부 | N20: [0205] - 서비스 불가 상황에 대한 세부적인 정의 없이 상담거래 자동연계는 고객 불만 요소가 될 수 있음. - 자동연계 요건은 삭제하고, 오류 코드에 대한 분석 확인 후 특정 코드에 대한 조건 처리로 요건 추가. - 실제 연계 처리는 공통업무가 아닌 각 업무개발팀에서 진행. | Q20: 20210205_UXUI(공통)_회의록_요구사항분석_로그인.인증.기타_ver1.0.docx | R20: 박준규 | S20: 공통(기타) | T20: N | U20: 미래컨택센터추진단 | V20: 송윤종 수석 | X20: N/A | Y20: 박형준 차장 권장우 대리 | AH20: 권영순부장
A21: Biz-061 | B21: 금액 입력 별도 키패드 제공 | C21: 기능 | D21: 요구사항정의 | E21: 신규 | F21: 구축요건정의서 | G21: BFE-23090 | H21: 금액 입력 별도 키패드 제공 | I21: - 금액 숫자 키패드 커스텀 적용 ex. 금액 Short-cut 단위 추가('백', '천', '만') 등 / '5' > '만' 버튼 입력시 '50,000원' 입력 ------------------------- 커스텀 키패드 사용범위 확인 필요(숫자 입력용 공용 키패드로 개발 필요) | K21: 개인뱅킹플랫폼부 | L21: UXUI | M21: 승인 | N21: [0205] - 금액입력 전용 키패드와 숫자 입력 키패드 커스텀 개발 진행. | Q21: 20210205_UXUI(공통)_회의록_요구사항분석_로그인.인증.기타_ver1.0.docx | R21: 박준규 | S21: 네이티브 | T21: N | U21: N | X21: 김원용 수석 | Y21: 박형준 차장 권장우 대리 | AB21: ● | AH21: 신재현이사
A22: Biz-162 | B22: 챗봇 기능 고도화 | C22: 기능 | D22: 요구사항정의 | E22: 신규 | F22: 구축요건정의서 | G22: BFE-23100 | H22: 챗봇 기능 고도화 | I22: - 先 진행(챗봇 고도화) 프로젝트에서 수용이 어려울 경우 통합검색 요건으로 변경 가능 ----------------------------------------------------------------------------------------- - 통합검색 內 음성인식(오픈소스) 기능 연계 추가 ㅇ 음성을 통한 검색결과 동일 표출(음성 인식 후 결과에 대한 해당 화면 자동 이동 기능 제공) - 자연어 검색을 통한 상품, 이벤트, 마케팅, FAQ 내용 검색 결과 제공 ------------------------------------------------ 통합검색 요건으로 변경(자연어 처리에 대한 구체화 필요) | K22: 개인뱅킹플랫폼부 스마트상담부 | L22: UXUI | M22: 승인 | N22: [0205] - 챗봇기능 고도화는 별도 프로젝트로 진행하며 통합검색에 키워드 입력시 음성인식 기능 제공에 대한 요건. - OS레벨에서 제공하는 기능을 기반으로 제공되며, 복잡한 금융용어에 대한 인식율 저하는 있을 수 있음. - 통합검색 등 각 업무별 적용은 담당 업무개발팀에서 진행. | Q22: 20210205_UXUI(공통)_회의록_요구사항분석_로그인.인증.기타_ver1.0.docx | R22: 박준규 | S22: 공통(기타) | T22: N | U22: 미래컨택센터추진단 | V22: 송윤종 수석 | X22: 권희영 차장 | Y22: 박형준 차장 권장우 대리 | AH22: 권영순부장
